Workbook
Name NativeTimeline_FECHA1: #N/A

Sheet TEMAS
B2: SECTOR | C2: RESP | D2: PRIORIDAD | E2: TEMA | F2: REVISÓN | G2: FECHA INICIO | H2: DÍAS TRANSCU | I2: FECHA OBJETIVO | J2: CANT. MODIF FECHA OBJETIVO | K2: DÍAS A FAVOR | L2: NIVEL DE AVANCE | M2: CERRADO
B3: CALIDAD | C3: RODRI | D3: 1 | E3: Exceso de sodio | F3: INDIVIDUAL | G3: 45992 | H3: =+IF(M3="SI","CERRADO",IF(G3="-","NO INICIADO",IF(I3="-","SIN FECHA OBJ.",IF(I3="--","EN PAUSA",TODAY()-G3)))) -> 115 | I3: 46081 | J3: 0 | K3: =IF(I3="DEFINIR","DEFINIR",IF(M3="SI","CERRADO",IF(I3="-","-",IF(I3="--","EN PAUSA",I3-TODAY())))) -> -26 | L3: 0.5 | M3: NO
B4: CALIDAD | C4: RODRI | D4: 1 | E4: BRCGS al día | F4: MESA | G4: 46023 | H4: =+IF(M4="SI","CERRADO",IF(G4="-","NO INICIADO",IF(I4="-","SIN FECHA OBJ.",IF(I4="--","EN PAUSA",TODAY()-G4)))) -> 84 | I4: 46202 | J4: 0 | K4: =IF(I4="DEFINIR","DEFINIR",IF(M4="SI","CERRADO",IF(I4="-","-",IF(I4="--","EN PAUSA",I4-TODAY())))) -> 95 | L4: 0.2 | M4: NO
B5: CALIDAD | C5: RODRI | D5: 2 | E5: Fórmulas comparativas: soja | F5: INDIVIDUAL | G5: 45962 | H5: =+IF(M5="SI","CERRADO",IF(G5="-","NO INICIADO",IF(I5="-","SIN FECHA OBJ.",IF(I5="--","EN PAUSA",TODAY()-G5)))) -> SIN FECHA OBJ. | I5: - | J5: 0 | K5: =IF(I5="DEFINIR","DEFINIR",IF(M5="SI","CERRADO",IF(I5="-","-",IF(I5="--","EN PAUSA",I5-TODAY())))) -> - | L5: 0.4 | M5: NO
B6: CALIDAD | C6: RODRI | D6: 2 | E6: Control de Calidad: Adit, Emb y Nuggets en app o excel | F6: INDIVIDUAL | G6: 46002 | H6: =+IF(M6="SI","CERRADO",IF(G6="-","NO INICIADO",IF(I6="-","SIN FECHA OBJ.",IF(I6="--","EN PAUSA",TODAY()-G6)))) -> SIN FECHA OBJ. | I6: - | J6: 0 | K6: =IF(I6="DEFINIR","DEFINIR",IF(M6="SI","CERRADO",IF(I6="-","-",IF(I6="--","EN PAUSA",I6-TODAY())))) -> - | L6: 0.5 | M6: NO
B7: CALIDAD | C7: RODRI | D7: 3 | E7: Pruebas grasa S en microondas | F7: INDIVIDUAL | G7: 46002 | H7: =+IF(M7="SI","CERRADO",IF(G7="-","NO INICIADO",IF(I7="-","SIN FECHA OBJ.",IF(I7="--","EN PAUSA",TODAY()-G7)))) -> SIN FECHA OBJ. | I7: - | J7: 0 | K7: =IF(I7="DEFINIR","DEFINIR",IF(M7="SI","CERRADO",IF(I7="-","-",IF(I7="--","EN PAUSA",I7-TODAY())))) -> - | L7: 0.2 | M7: NO
B8: CALIDAD | C8: RODRI | D8: - | E8: Cambio de foodscan | F8: INDIVIDUAL | G8: 45962 | H8: =+IF(M8="SI","CERRADO",IF(G8="-","NO INICIADO",IF(I8="-","SIN FECHA OBJ.",IF(I8="--","EN PAUSA",TODAY()-G8)))) -> CERRADO | I8: 46041 | J8: 1 | K8: =IF(I8="DEFINIR","DEFINIR",IF(M8="SI","CERRADO",IF(I8="-","-",IF(I8="--","EN PAUSA",I8-TODAY())))) -> CERRADO | L8: 0.9 | M8: SI
B9: CALIDAD | C9: RODRI | D9: - | E9: Etiquetas aprobadas vs fechador | F9: INDIVIDUAL | G9: 46002 | H9: =+IF(M9="SI","CERRADO",IF(G9="-","NO INICIADO",IF(I9="-","SIN FECHA OBJ.",IF(I9="--","EN PAUSA",TODAY()-G9)))) -> CERRADO | I9: 46037 | J9: 1 | K9: =IF(I9="DEFINIR","DEFINIR",IF(M9="SI","CERRADO",IF(I9="-","-",IF(I9="--","EN PAUSA",I9-TODAY())))) -> CERRADO | L9: 1 | M9: SI
B10: PRODUCCIÓN | C10: JULIO | D10: 1 | E10: Placa de 11 | F10: MESA | G10: 45976 | H10: =+IF(M10="SI","CERRADO",IF(G10="-","NO INICIADO",IF(I10="-","SIN FECHA OBJ.",IF(I10="--","EN PAUSA",TODAY()-G10)))) -> SIN FECHA OBJ. | I10: - | J10: 0 | K10: =IF(I10="DEFINIR","DEFINIR",IF(M10="SI","CERRADO",IF(I10="-","-",IF(I10="--","EN PAUSA",I10-TODAY())))) -> - | L10: 0.6 | M10: NO
B11: PRODUCCIÓN | C11: JULIO | D11: 1 | E11: Reducir batch de 700 | F11: MESA | G11: 46037 | H11: =+IF(M11="SI","CERRADO",IF(G11="-","NO INICIADO",IF(I11="-","SIN FECHA OBJ.",IF(I11="--","EN PAUSA",TODAY()-G11)))) -> SIN FECHA OBJ. | I11: - | J11: 0 | K11: =IF(I11="DEFINIR","DEFINIR",IF(M11="SI","CERRADO",IF(I11="-","-",IF(I11="--","EN PAUSA",I11-TODAY())))) -> - | L11: 0.5 | M11: NO
B12: PRODUCCIÓN | C12: JULIO | D12: 1 | E12: Reproceso con etiqueta | F12: MESA | G12: 46001 | H12: =+IF(M12="SI","CERRADO",IF(G12="-","NO INICIADO",IF(I12="-","SIN FECHA OBJ.",IF(I12="--","EN PAUSA",TODAY()-G12)))) -> SIN FECHA OBJ. | I12: - | J12: 0 | K12: =IF(I12="DEFINIR","DEFINIR",IF(M12="SI","CERRADO",IF(I12="-","-",IF(I12="--","EN PAUSA",I12-TODAY())))) -> - | L12: 0 | M12: NO
B13: PRODUCCIÓN | C13: JULIO | D13: 1 | E13: Merma recupero para venta | F13: INDIVIDUAL | G13: 46001 | H13: =+IF(M13="SI","CERRADO",IF(G13="-","NO INICIADO",IF(I13="-","SIN FECHA OBJ.",IF(I13="--","EN PAUSA",TODAY()-G13)))) -> SIN FECHA OBJ. | I13: - | J13: 0 | K13: =IF(I13="DEFINIR","DEFINIR",IF(M13="SI","CERRADO",IF(I13="-","-",IF(I13="--","EN PAUSA",I13-TODAY())))) -> - | L13: 0 | M13: NO
B14: PRODUCCIÓN | C14: JULIO | D14: 2 | E14: Nueva dotación de producción | F14: INDIVIDUAL | G14: 46054 | H14: =+IF(M14="SI","CERRADO",IF(G14="-","NO INICIADO",IF(I14="-","SIN FECHA OBJ.",IF(I14="--","EN PAUSA",TODAY()-G14)))) -> 53 | I14: 46142 | J14: 0 | K14: =IF(I14="DEFINIR","DEFINIR",IF(M14="SI","CERRADO",IF(I14="-","-",IF(I14="--","EN PAUSA",I14-TODAY())))) -> 35 | L14: 0.3 | M14: NO
B15: PRODUCCIÓN | C15: JULIO | D15: P | E15: Hamburguesas con mezcla de cerdo - (lograr el producto) | F15: INDIVIDUAL | G15: 45962 | H15: =+IF(M15="SI","CERRADO",IF(G15="-","NO INICIADO",IF(I15="-","SIN FECHA OBJ.",IF(I15="--","EN PAUSA",TODAY()-G15)))) -> EN PAUSA | I15: -- | J15: 0 | K15: =IF(I15="DEFINIR","DEFINIR",IF(M15="SI","CERRADO",IF(I15="-","-",IF(I15="--","EN PAUSA",I15-TODAY())))) -> EN PAUSA | L15: 0 | M15: NO
B16: PRODUCCIÓN | C16: JULIO | D16: P | E16: Chorizo cerdo (recorte + panceta) - (lograr el producto) | F16: INDIVIDUAL | G16: 45962 | H16: =+IF(M16="SI","CERRADO",IF(G16="-","NO INICIADO",IF(I16="-","SIN FECHA OBJ.",IF(I16="--","EN PAUSA",TODAY()-G16)))) -> EN PAUSA | I16: -- | J16: 0 | K16: =IF(I16="DEFINIR","DEFINIR",IF(M16="SI","CERRADO",IF(I16="-","-",IF(I16="--","EN PAUSA",I16-TODAY())))) -> EN PAUSA | L16: 0 | M16: NO
B17: PRODUCCIÓN | C17: JULIO | D17: - | E17: Hamburguesa 6mm - (lograr el producto) | F17: INDIVIDUAL | G17: 45931 | H17: =+IF(M17="SI","CERRADO",IF(G17="-","NO INICIADO",IF(I17="-","SIN FECHA OBJ.",IF(I17="--","EN PAUSA",TODAY()-G17)))) -> CERRADO | I17: - | J17: 0 | K17: =IF(I17="DEFINIR","DEFINIR",IF(M17="SI","CERRADO",IF(I17="-","-",IF(I17="--","EN PAUSA",I17-TODAY())))) -> CERRADO | L17: 0.5 | M17: SI
B18: PRODUCCIÓN | C18: JULIO | D18: - | E18: Selladora de pulpetas CPC - (lograr el producto) | F18: MESA | G18: 45962 | H18: =+IF(M18="SI","CERRADO",IF(G18="-","NO INICIADO",IF(I18="-","SIN FECHA OBJ.",IF(I18="--","EN PAUSA",TODAY()-G18)))) -> CERRADO | I18: - | J18: 0 | K18: =IF(I18="DEFINIR","DEFINIR",IF(M18="SI","CERRADO",IF(I18="-","-",IF(I18="--","EN PAUSA",I18-TODAY())))) -> CERRADO | L18: 1 | M18: SI
B19: ABASTECIMIENTO | C19: CARLOS | D19: 1 | E19: Implementar Quadmins | F19: INDIVIDUAL | G19: 45931 | H19: =+IF(M19="SI","CERRADO",IF(G19="-","NO INICIADO",IF(I19="-","SIN FECHA OBJ.",IF(I19="--","EN PAUSA",TODAY()-G19)))) -> 176 | I19: 46022 | J19: 0 | K19: =IF(I19="DEFINIR","DEFINIR",IF(M19="SI","CERRADO",IF(I19="-","-",IF(I19="--","EN PAUSA",I19-TODAY())))) -> -85 | L19: 0.7 | M19: NO
B20: ABASTECIMIENTO | C20: CARLOS | D20: 1 | E20: Orden HH con producción | F20: INDIVIDUAL | G20: 45931 | H20: =+IF(M20="SI","CERRADO",IF(G20="-","NO INICIADO",IF(I20="-","SIN FECHA OBJ.",IF(I20="--","EN PAUSA",TODAY()-G20)))) -> SIN FECHA OBJ. | I20: - | J20: 0 | K20: =IF(I20="DEFINIR","DEFINIR",IF(M20="SI","CERRADO",IF(I20="-","-",IF(I20="--","EN PAUSA",I20-TODAY())))) -> - | L20: 0 | M20: NO
B21: ABASTECIMIENTO | C21: CARLOS | D21: - | E21: Implementar Escobar/Ituzaingó | F21: MESA | G21: 45962 | H21: =+IF(M21="SI","CERRADO",IF(G21="-","NO INICIADO",IF(I21="-","SIN FECHA OBJ.",IF(I21="--","EN PAUSA",TODAY()-G21)))) -> CERRADO | I21: 46011 | J21: 0 | K21: =IF(I21="DEFINIR","DEFINIR",IF(M21="SI","CERRADO",IF(I21="-","-",IF(I21="--","EN PAUSA",I21-TODAY())))) -> CERRADO | L21: 1 | M21: SI
B22: ABASTECIMIENTO | C22: CARLOS | D22: - | E22: Rampa niveladora para descarga de semis pareja | F22: INDIVIDUAL | G22: 45962 | H22: =+IF(M22="SI","CERRADO",IF(G22="-","NO INICIADO",IF(I22="-","SIN FECHA OBJ.",IF(I22="--","EN PAUSA",TODAY()-G22)))) -> CERRADO | I22: 46022 | J22: 0 | K22: =IF(I22="DEFINIR","DEFINIR",IF(M22="SI","CERRADO",IF(I22="-","-",IF(I22="--","EN PAUSA",I22-TODAY())))) -> CERRADO | L22: 1 | M22: SI
B23: ABASTECIMIENTO | C23: CARLOS | D23: - | E23: Tabla carga equipos de carga | F23: INDIVIDUAL | G23: 45962 | H23: =+IF(M23="SI","CERRADO",IF(G23="-","NO INICIADO",IF(I23="-","SIN FECHA OBJ.",IF(I23="--","EN PAUSA",TODAY()-G23)))) -> CERRADO | I23: 46011 | J23: 0 | K23: =IF(I23="DEFINIR","DEFINIR",IF(M23="SI","CERRADO",IF(I23="-","-",IF(I23="--","EN PAUSA",I23-TODAY())))) -> CERRADO | L23: 1 | M23: SI
B24: HIGIENE | C24: DAVID | D24: 1 | E24: Lavado de cintas automático | F24: INDIVIDUAL | G24: 45931 | H24: =+IF(M24="SI","CERRADO",IF(G24="-","NO INICIADO",IF(I24="-","SIN FECHA OBJ.",IF(I24="--","EN PAUSA",TODAY()-G24)))) -> 176 | I24: 46081 | J24: 1 | K24: =IF(I24="DEFINIR","DEFINIR",IF(M24="SI","CERRADO",IF(I24="-","-",IF(I24="--","EN PAUSA",I24-TODAY())))) -> -26 | L24: 0.2 | M24: NO
B25: HIGIENE | C25: DAVID | D25: 2 | E25: Vestuaristas + cerrado de vestuario menos en almuerzo | F25: MESA | G25: 45962 | H25: =+IF(M25="SI","CERRADO",IF(G25="-","NO INICIADO",IF(I25="-","SIN FECHA OBJ.",IF(I25="--","EN PAUSA",TODAY()-G25)))) -> 145 | I25: 46052 | J25: 1 | K25: =IF(I25="DEFINIR","DEFINIR",IF(M25="SI","CERRADO",IF(I25="-","-",IF(I25="--","EN PAUSA",I25-TODAY())))) -> -55 | L25: 0.9 | M25: NO
B26: HIGIENE | C26: DAVID | D26: 3 | E26: Lavarropas - nuevo | F26: INDIVIDUAL | G26: 46052 | H26: =+IF(M26="SI","CERRADO",IF(G26="-","NO INICIADO",IF(I26="-","SIN FECHA OBJ.",IF(I26="--","EN PAUSA",TODAY()-G26)))) -> SIN FECHA OBJ. | I26: - | J26: 0 | K26: =IF(I26="DEFINIR","DEFINIR",IF(M26="SI","CERRADO",IF(I26="-","-",IF(I26="--","EN PAUSA",I26-TODAY())))) -> - | L26: 0.2 | M26: NO
B27: HIGIENE | C27: DAVID | D27: 3 | E27: Frecuencias de limpieza | F27: INDIVIDUAL | G27: 46077 | H27: =+IF(M27="SI","CERRADO",IF(G27="-","NO INICIADO",IF(I27="-","SIN FECHA OBJ.",IF(I27="--","EN PAUSA",TODAY()-G27)))) -> SIN FECHA OBJ. | I27: - | J27: 0 | K27: =IF(I27="DEFINIR","DEFINIR",IF(M27="SI","CERRADO",IF(I27="-","-",IF(I27="--","EN PAUSA",I27-TODAY())))) -> - | L27: 0 | M27: NO
B28: HIGIENE | C28: DAVID | D28: 3 | E28: Secamanos (5), guillotinas (4) y autocortes (5) | F28: INDIVIDUAL | G28: 45962 | H28: =+IF(M28="SI","CERRADO",IF(G28="-","NO INICIADO",IF(I28="-","SIN FECHA OBJ.",IF(I28="--","EN PAUSA",TODAY()-G28)))) -> 145 | I28: 46053 | J28: 0 | K28: =IF(I28="DEFINIR","DEFINIR",IF(M28="SI","CERRADO",IF(I28="-","-",IF(I28="--","EN PAUSA",I28-TODAY())))) -> -54 | L28: 0.99 | M28: NO
B29: HIGIENE | C29: DAVID | D29: - | E29: Lavado con agua caliente (contenedor y disificación) | F29: INDIVIDUAL | G29: 45931 | H29: =+IF(M29="SI","CERRADO",IF(G29="-","NO INICIADO",IF(I29="-","SIN FECHA OBJ.",IF(I29="--","EN PAUSA",TODAY()-G29)))) -> CERRADO | I29: 45976 | J29: 0 | K29: =IF(I29="DEFINIR","DEFINIR",IF(M29="SI","CERRADO",IF(I29="-","-",IF(I29="--","EN PAUSA",I29-TODAY())))) -> CERRADO | L29: 1 | M29: SI
B30: HIGIENE | C30: DAVID | D30: - | E30: Máquina a vapor | F30: MESA | G30: 45931 | H30: =+IF(M30="SI","CERRADO",IF(G30="-","NO INICIADO",IF(I30="-","SIN FECHA OBJ.",IF(I30="--","EN PAUSA",TODAY()-G30)))) -> CERRADO | I30: 45992 | J30: 0 | K30: =IF(I30="DEFINIR","DEFINIR",IF(M30="SI","CERRADO",IF(I30="-","-",IF(I30="--","EN PAUSA",I30-TODAY())))) -> CERRADO | L30: 1 | M30: SI
B31: HIGIENE | C31: DAVID | D31: - | E31: Limpiezas diarias comedor | F31: MESA | G31: 45981 | H31: =+IF(M31="SI","CERRADO",IF(G31="-","NO INICIADO",IF(I31="-","SIN FECHA OBJ.",IF(I31="--","EN PAUSA",TODAY()-G31)))) -> CERRADO | I31: 45991 | J31: 0 | K31: =IF(I31="DEFINIR","DEFINIR",IF(M31="SI","CERRADO",IF(I31="-","-",IF(I31="--","EN PAUSA",I31-TODAY())))) -> CERRADO | L31: 1 | M31: SI
B32: MANTENIMIENTO | C32: FACU | D32: 1 | E32: Trafo: análisis, informe y acciones a tomar (Electrotech) | F32: INDIVIDUAL | G32: 45931 | H32: =+IF(M32="SI","CERRADO",IF(G32="-","NO INICIADO",IF(I32="-","SIN FECHA OBJ.",IF(I32="--","EN PAUSA",TODAY()-G32)))) -> 176 | I32: 46081 | J32: 1 | K32: =IF(I32="DEFINIR","DEFINIR",IF(M32="SI","CERRADO",IF(I32="-","-",IF(I32="--","EN PAUSA",I32-TODAY())))) -> -26 | L32: 0.7 | M32: NO
B33: MANTENIMIENTO | C33: FACU | D33: 1 | E33: Torre de enfriamiento | F33: INDIVIDUAL | G33: 45931 | H33: =+IF(M33="SI","CERRADO",IF(G33="-","NO INICIADO",IF(I33="-","SIN FECHA OBJ.",IF(I33="--","EN PAUSA",TODAY()-G33)))) -> 176 | I33: 46118 | J33: 1 | K33: =IF(I33="DEFINIR","DEFINIR",IF(M33="SI","CERRADO",IF(I33="-","-",IF(I33="--","EN PAUSA",I33-TODAY())))) -> 11 | L33: 0.98 | M33: NO
B34: MANTENIMIENTO | C34: FACU | D34: 1 | E34: Preventivo GYRO | F34: INDIVIDUAL | G34: 45931 | H34: =+IF(M34="SI","CERRADO",IF(G34="-","NO INICIADO",IF(I34="-","SIN FECHA OBJ.",IF(I34="--","EN PAUSA",TODAY()-G34)))) -> 176 | I34: 46111 | J34: 0 | K34: =IF(I34="DEFINIR","DEFINIR",IF(M34="SI","CERRADO",IF(I34="-","-",IF(I34="--","EN PAUSA",I34-TODAY())))) -> 4 | L34: 0.5 | M34: NO
B35: MANTENIMIENTO | C35: FACU | D35: 1 | E35: Preventivo Formax | F35: INDIVIDUAL | G35: 46002 | H35: =+IF(M35="SI","CERRADO",IF(G35="-","NO INICIADO",IF(I35="-","SIN FECHA OBJ.",IF(I35="--","EN PAUSA",TODAY()-G35)))) -> 105 | I35: 46111 | J35: 0 | K35: =IF(I35="DEFINIR","DEFINIR",IF(M35="SI","CERRADO",IF(I35="-","-",IF(I35="--","EN PAUSA",I35-TODAY())))) -> 4 | L35: 0.2 | M35: NO
B36: MANTENIMIENTO | C36: FACU | D36: 1 | E36: Arreglo piso 1.2 y 1.3 | F36: INDIVIDUAL | G36: 46106 | H36: =+IF(M36="SI","CERRADO",IF(G36="-","NO INICIADO",IF(I36="-","SIN FECHA OBJ.",IF(I36="--","EN PAUSA",TODAY()-G36)))) -> SIN FECHA OBJ. | I36: - | J36: 0 | K36: =IF(I36="DEFINIR","DEFINIR",IF(M36="SI","CERRADO",IF(I36="-","-",IF(I36="--","EN PAUSA",I36-TODAY())))) -> - | L36: 0 | M36: NO
B37: MANTENIMIENTO | C37: FACU | D37: 2 | E37: Pulmón | F37: MESA | G37: 46054 | H37: =+IF(M37="SI","CERRADO",IF(G37="-","NO INICIADO",IF(I37="-","SIN FECHA OBJ.",IF(I37="--","EN PAUSA",TODAY()-G37)))) -> SIN FECHA OBJ. | I37: - | J37: 0 | K37: =IF(I37="DEFINIR","DEFINIR",IF(M37="SI","CERRADO",IF(I37="-","-",IF(I37="--","EN PAUSA",I37-TODAY())))) -> - | L37: 0 | M37: NO
B38: MANTENIMIENTO | C38: FACU | D38: 2 | E38: Bomba de lavado | F38: INDIVIDUAL | G38: 45931 | H38: =+IF(M38="SI","CERRADO",IF(G38="-","NO INICIADO",IF(I38="-","SIN FECHA OBJ.",IF(I38="--","EN PAUSA",TODAY()-G38)))) -> 176 | I38: 46081 | J38: 1 | K38: =IF(I38="DEFINIR","DEFINIR",IF(M38="SI","CERRADO",IF(I38="-","-",IF(I38="--","EN PAUSA",I38-TODAY())))) -> -26 | L38: 0.8 | M38: NO
B39: MANTENIMIENTO | C39: FACU | D39: 2 | E39: Goteras: dep. cajas, estuchado, palletizado | F39: INDIVIDUAL | G39: 45962 | H39: =+IF(M39="SI","CERRADO",IF(G39="-","NO INICIADO",IF(I39="-","SIN FECHA OBJ.",IF(I39="--","EN PAUSA",TODAY()-G39)))) -> 145 | I39: 46081 | J39: 0 | K39: =IF(I39="DEFINIR","DEFINIR",IF(M39="SI","CERRADO",IF(I39="-","-",IF(I39="--","EN PAUSA",I39-TODAY())))) -> -26 | L39: 0.5 | M39: NO
B40: MANTENIMIENTO | C40: FACU | D40: 2 | E40: Evaporadores 03 y producción | F40: INDIVIDUAL | G40: 46058 | H40: =+IF(M40="SI","CERRADO",IF(G40="-","NO INICIADO",IF(I40="-","SIN FECHA OBJ.",IF(I40="--","EN PAUSA",TODAY()-G40)))) -> SIN FECHA OBJ. | I40: - | J40: 0 | K40: =IF(I40="DEFINIR","DEFINIR",IF(M40="SI","CERRADO",IF(I40="-","-",IF(I40="--","EN PAUSA",I40-TODAY())))) -> - | L40: 0.7 | M40: NO
B41: MANTENIMIENTO | C41: FACU | D41: 2 | E41: Tomra | F41: MESA | G41: 45962 | H41: =+IF(M41="SI","CERRADO",IF(G41="-","NO INICIADO",IF(I41="-","SIN FECHA OBJ.",IF(I41="--","EN PAUSA",TODAY()-G41)))) -> 145 | I41: 46081 | J41: 0 | K41: =IF(I41="DEFINIR","DEFINIR",IF(M41="SI","CERRADO",IF(I41="-","-",IF(I41="--","EN PAUSA",I41-TODAY())))) -> -26 | L41: 0.2 | M41: NO
...

Sheet MES CERRADO
D2: 44927 | E2: 44958 | F2: 44986 | G2: 45017 | H2: 45047 | I2: 45078 | J2: 45108 | K2: 45139 | L2: 45170 | M2: 45200 | N2: 45231 | O2: 45261 | P2: 45292 | Q2: 45323 | R2: 45352 | S2: 45383 | T2: 45413 | U2: 45444 | V2: 45474 | W2: 45505 | X2: 45536 | Y2: 45566 | Z2: 45597 | AA2: 45627 | AB2: 45658 | AC2: 45689 | AD2: 45717 | AE2: 45748 | AF2: 45778 | AG2: 45809 | AH2: 45839 | AI2: 45870 | AJ2: 45901 | AK2: 45931 | AL2: 45962 | AM2: 45992 | AN2: 46023 | AO2: 46054 | BA2: 2023 | BB2: 2024 | BC2: 2025
B3: PRODUCCIÓN REAL | C3: TN | D3: 992 | E3: 957 | F3: 1079 | G3: 1120 | H3: 1068 | I3: 983 | J3: 920 | K3: 987 | L3: 836 | M3: 887 | N3: 1034 | O3: 735 | P3: 863 | Q3: 654 | R3: 801 | S3: 826 | T3: 893 | U3: 691 | V3: 907 | W3: 953 | X3: 948 | Y3: 1074 | Z3: 1064 | AA3: 1082 | AB3: 1220 | AC3: 1151 | AD3: 1134 | AE3: 1126 | AF3: 1127.684 | AG3: 816.474 | AH3: =SUMIFS('TABLERO DIARIO'!$I$6:$ZZ$6,'TABLERO DIARIO'!$I$2:$ZZ$2,">="&DATE(2025,MONTH(AH$2),1),'TABLERO DIARIO'!$I$2:$ZZ$2,"<="&EOMONTH(AH$2,0))/1000 -> 1119.4608 | AI3: =SUMIFS('TABLERO DIARIO'!$I$6:$ZZ$6,'TABLERO DIARIO'!$I$2:$ZZ$2,">="&DATE(2025,MONTH(AI$2),1),'TABLERO DIARIO'!$I$2:$ZZ$2,"<="&EOMONTH(AI$2,0))/1000 -> 947.0842 | AJ3: =SUMIFS('TABLERO DIARIO'!$I$6:$ABL$6,'TABLERO DIARIO'!$I$2:$ABL$2,">="&DATE(2025,MONTH(AJ$2),1),'TABLERO DIARIO'!$I$2:$ABL$2,"<="&EOMONTH(AJ$2,0))/1000 -> 1009.3253 | AK3: =SUMIFS('TABLERO DIARIO'!$I$6:$AEV$6,'TABLERO DIARIO'!$I$2:$AEV$2,">="&DATE(2025,MONTH(AK$2),1),'TABLERO DIARIO'!$I$2:$AEV$2,"<="&EOMONTH(AK$2,0))/1000 -> 1079.8902 | AL3: =SUMIFS('TABLERO DIARIO'!$I$6:$AMA$6,'TABLERO DIARIO'!$I$2:$AMA$2,">="&DATE(2025,MONTH(AL$2),1),'TABLERO DIARIO'!$I$2:$AMA$2,"<="&EOMONTH(AL$2,0))/1000 -> 984.7747 | AM3: =SUMIFS('TABLERO DIARIO'!$I$6:$AMA$6,'TABLERO DIARIO'!$I$2:$AMA$2,">="&DATE(2025,MONTH(AM$2),1),'TABLERO DIARIO'!$I$2:$AMA$2,"<="&EOMONTH(AM$2,0))/1000 -> 1089.6389 | AN3: =SUMIFS('TABLERO DIARIO'!$ALW$6:$ASW$6,'TABLERO DIARIO'!$ALW$2:$ASW$2,">="&DATE(2026,MONTH(AN$2),1),'TABLERO DIARIO'!$ALW$2:$ASW$2,"<="&EOMONTH(AN$2,0))/1000 -> 1163.6429 | AO3: =SUMIFS('TABLERO DIARIO'!$ALW$6:$ASW$6,'TABLERO DIARIO'!$ALW$2:$ASW$2,">="&DATE(2026,MONTH(AO$2),1),'TABLERO DIARIO'!$ALW$2:$ASW$2,"<="&EOMONTH(AO$2,0))/1000 -> 1070.7313 | BA3: =IFERROR(AVERAGE(D3:O3),"-") -> 966.5 | BB3: =IFERROR(AVERAGE(P3:AA3),"-") -> 896.33333 | BC3: =IFERROR(SUMIFS(AB3:AM3,AB3:AM3,"<>0",AB3:AM3,"<>-",AB3:AM3,"<>",AB3:AM3,"<> ")/COUNTIFS(AB3:AM3,"<>0",AB3:AM3,"<>-",AB3:AM3,"<>",AB3:AM3,"<> "),"-") -> 1067.111
B4: PRODUCCIÓN OBJETIVO | C4: TN | D4: 1141 | E4: 1047 | F4: 1119 | G4: 1071 | H4: 1096 | I4: 1065 | J4: 1108 | K4: 966 | L4: 882 | M4: 840 | N4: 1008 | O4: 798 | P4: 924 | Q4: 798 | R4: 777 | S4: 820 | T4: 902 | U4: 672 | V4: 940 | W4: 955 | X4: 1099 | Y4: 1107 | Z4: 1087 | AA4: 1037 | AB4: 1176 | AC4: 1126 | AD4: 1148 | AE4: 1110 | AF4: 1185 | AG4: 850 | AH4: 1140 | AI4: =+CALENDARIO!AV23 -> 945 | AJ4: =+CALENDARIO!BD23 -> 1070 | AK4: =+CALENDARIO!BL23 -> 1090 | AL4: =+CALENDARIO!BT23 -> 1015 | AM4: =+CALENDARIO!CB23 -> 1115 | AN4: =+CALENDARIO!CJ23 -> 1105 | AO4: =+CALENDARIO!CR23 -> 1050 | BA4: =IFERROR(AVERAGE(D4:O4),"-") -> 1011.75 | BB4: =IFERROR(AVERAGE(P4:AA4),"-") -> 926.5 | BC4: =IFERROR(SUMIFS(AB4:AM4,AB4:AM4,"<>0",AB4:AM4,"<>-",AB4:AM4,"<>",AB4:AM4,"<> ")/COUNTIFS(AB4:AM4,"<>0",AB4:AM4,"<>-",AB4:AM4,"<>",AB4:AM4,"<> "),"-") -> 1080.8333
B5: PRODUCCIÓN REAL VS OBJETIVO | C5: % | D5: 0.87 | E5: 0.91 | F5: 0.96 | G5: 1.05 | H5: 0.97 | I5: 0.92 | J5: 0.83 | K5: 1.02 | L5: 0.95 | M5: 1.06 | N5: 1.03 | O5: 0.92 | P5: 0.93 | Q5: 0.82 | R5: 1.03 | S5: 1.01 | T5: 0.99 | U5: 1.03 | V5: 0.97 | W5: 1 | X5: 0.86 | Y5: 0.97 | Z5: 0.98 | AA5: 1.04 | AB5: 1.04 | AC5: =IFERROR(IF(AC3<>0,AC3/AC4,"-"),"FD") -> 1.0222025 | AD5: =IFERROR(IF(AD3<>0,AD3/AD4,"-"),"FD") -> 0.98780488 | AE5: =IFERROR(IF(AE3<>0,AE3/AE4,"-"),"FD") -> 1.0144144 | AF5: =IFERROR(IF(AF3<>0,AF3/AF4,"-"),"FD") -> 0.95163207 | AG5: =IFERROR(IF(AG3<>0,AG3/AG4,"-"),"FD") -> 0.96055765 | AH5: =IFERROR(IF(AH3<>0,AH3/AH4,"-"),"FD") -> 0.98198316 | AI5: =IFERROR(IF(AI3<>0,AI3/AI4,"-"),"FD") -> 1.0022055 | AJ5: =IFERROR(IF(AJ3<>0,AJ3/AJ4,"-"),"FD") -> 0.94329467 | ... AO5: =IFERROR(IF(AO3<>0,AO3/AO4,"-"),"FD") -> 1.0197441 | BA5: =IFERROR(IF(BA3<>0,BA3/BA4,"-"),"FD") -> 0.95527551 | BB5: =IFERROR(IF(BB3<>0,BB3/BB4,"-"),"FD") -> 0.96744019 | BC5: =IFERROR(SUMIFS(AB5:AM5,AB5:AM5,"<>0",AB5:AM5,"<>-",AB5:AM5,"<>",AB5:AM5,"<> ")/COUNTIFS(AB5:AM5,"<>0",AB5:AM5,"<>-",AB5:AM5,"<>",AB5:AM5,"<> "),"-") -> 0.98685798
B6: PRODUCCIÓN PROM POR DÍA | C6: TN | D6: - | E6: - | F6: - | G6: - | H6: - | I6: - | J6: - | K6: - | L6: - | M6: - | N6: - | P6: - | Q6: - | R6: - | S6: - | T6: - | U6: - | V6: - | W6: - | X6: - | Y6: - | Z6: - | AA6: - | AB6: - | AC6: =(SUMIFS('TABLERO DIARIO'!$I$6:$ZZ$6,'TABLERO DIARIO'!$I$2:$ZZ$2,">="&DATE(2025,MONTH(AC$2),1),'TABLERO DIARIO'!$I$2:$ZZ$2,"<="&EOMONTH(AC$2,0))/COUNTIFS('TABLERO DIARIO'!$I$2:$ZZ$2,">="&DATE(2025,MONTH(AC$2),1),'TABLERO DIARIO'!$I$2:$ZZ$2,"<="&EOMONTH(AC$2,0),'TABLERO DIARIO'!$I$6:$ZZ$6,"<>0"))/1000 -> 41.102932 | AD6: =(SUMIFS('TABLERO DIARIO'!$I$6:$ZZ$6,'TABLERO DIARIO'!$I$2:$ZZ$2,">="&DATE(2025,MONTH(AD$2),1),'TABLERO DIARIO'!$I$2:$ZZ$2,"<="&EOMONTH(AD$2,0))/COUNTIFS('TABLERO DIARIO'!$I$2:$ZZ$2,">="&DATE(2025,MONTH(AD$2),1),'TABLERO DIARIO'!$I$2:$ZZ$2,"<="&EOMONTH(AD$2,0),'TABLERO DIARIO'!$I$6:$ZZ$6,"<>0"))/1000 -> 40.506011 | AE6: =(SUMIFS('TABLERO DIARIO'!$I$6:$ZZ$6,'TABLERO DIARIO'!$I$2:$ZZ$2,">="&DATE(2025,MONTH(AE$2),1),'TABLERO DIARIO'!$I$2:$ZZ$2,"<="&EOMONTH(AE$2,0))/COUNTIFS('TABLERO DIARIO'!$I$2:$ZZ$2,">="&DATE(2025,MONTH(AE$2),1),'TABLERO DIARIO'!$I$2:$ZZ$2,"<="&EOMONTH(AE$2,0),'TABLERO DIARIO'!$I$6:$ZZ$6,"<>0"))/1000 -> 43.317158 | AF6: =(SUMIFS('TABLERO DIARIO'!$I$6:$ZZ$6,'TABLERO DIARIO'!$I$2:$ZZ$2,">="&DATE(2025,MONTH(AF$2),1),'TABLERO DIARIO'!$I$2:$ZZ$2,"<="&EOMONTH(AF$2,0))/COUNTIFS('TABLERO DIARIO'!$I$2:$ZZ$2,">="&DATE(2025,MONTH(AF$2),1),'TABLERO DIARIO'!$I$2:$ZZ$2,"<="&EOMONTH(AF$2,0),'TABLERO DIARIO'!$I$6:$ZZ$6,"<>0"))/1000 -> 45.10734 | AG6: =(SUMIFS('TABLERO DIARIO'!$I$6:$ZZ$6,'TABLERO DIARIO'!$I$2:$ZZ$2,">="&DATE(2025,MONTH(AG$2),1),'TABLERO DIARIO'!$I$2:$ZZ$2,"<="&EOMONTH(AG$2,0))/COUNTIFS('TABLERO DIARIO'!$I$2:$ZZ$2,">="&DATE(2025,MONTH(AG$2),1),'TABLERO DIARIO'!$I$2:$ZZ$2,"<="&EOMONTH(AG$2,0),'TABLERO DIARIO'!$I$6:$ZZ$6,"<>0"))/1000 -> 42.966907 | AH6: =(SUMIFS('TABLERO DIARIO'!$I$6:$ZZ$6,'TABLERO DIARIO'!$I$2:$ZZ$2,">="&DATE(2025,MONTH(AH$2),1),'TABLERO DIARIO'!$I$2:$ZZ$2,"<="&EOMONTH(AH$2,0))/COUNTIFS('TABLERO DIARIO'!$I$2:$ZZ$2,">="&DATE(2025,MONTH(AH$2),1),'TABLERO DIARIO'!$I$2:$ZZ$2,"<="&EOMONTH(AH$2,0),'TABLERO DIARIO'!$I$6:$ZZ$6,"<>0"))/1000 -> 43.056185 | AI6: =IFERROR((SUMIFS('TABLERO DIARIO'!$I$6:$ZZ$6,'TABLERO DIARIO'!$I$2:$ZZ$2,">="&DATE(2025,MONTH(AI$2),1),'TABLERO DIARIO'!$I$2:$ZZ$2,"<="&EOMONTH(AI$2,0))/COUNTIFS('TABLERO DIARIO'!$I$2:$ZZ$2,">="&DATE(2025,MONTH(AI$2),1),'TABLERO DIARIO'!$I$2:$ZZ$2,"<="&EOMONTH(AI$2,0),'TABLERO DIARIO'!$I$6:$ZZ$6,"<>0"))/1000,"-") -> 45.099248 | AJ6: =IFERROR((SUMIFS('TABLERO DIARIO'!$I$6:$ABL$6,'TABLERO DIARIO'!$I$2:$ABL$2,">="&DATE(2025,MONTH(AJ$2),1),'TABLERO DIARIO'!$I$2:$ABL$2,"<="&EOMONTH(AJ$2,0))/COUNTIFS('TABLERO DIARIO'!$I$2:$ABL$2,">="&DATE(2025,MONTH(AJ$2),1),'TABLERO DIARIO'!$I$2:$ABL$2,"<="&EOMONTH(AJ$2,0),'TABLERO DIARIO'!$I$6:$ABL$6,"<>0"))/1000,"-") -> 42.055221 | AK6: =IFERROR((SUMIFS('TABLERO DIARIO'!$I$6:$AEV$6,'TABLERO DIARIO'!$I$2:$AEV$2,">="&DATE(2025,MONTH(AK$2),1),'TABLERO DIARIO'!$I$2:$AEV$2,"<="&EOMONTH(AK$2,0))/COUNTIFS('TABLERO DIARIO'!$I$2:$AEV$2,">="&DATE(2025,MONTH(AK$2),1),'TABLERO DIARIO'!$I$2:$AEV$2,"<="&EOMONTH(AK$2,0),'TABLERO DIARIO'!$I$6:$AEV$6,"<>0"))/1000,"-") -> 38.567507 | AL6: =IFERROR((SUMIFS('TABLERO DIARIO'!$AEV$6:$AMA$6,'TABLERO DIARIO'!$AEV$2:$AMA$2,">="&DATE(2025,MONTH(AL$2),1),'TABLERO DIARIO'!$AEV$2:$AMA$2,"<="&EOMONTH(AL$2,0))/COUNTIFS('TABLERO DIARIO'!$AEV$2:$AMA$2,">="&DATE(2025,MONTH(AL$2),1),'TABLERO DIARIO'!$AEV$2:$AMA$2,"<="&EOMONTH(AL$2,0),'TABLERO DIARIO'!$AEV$6:$AMA$6,"<>0"))/1000,"-") -> 37.87595 | AM6: =IFERROR((SUMIFS('TABLERO DIARIO'!$AEV$6:$AMA$6,'TABLERO DIARIO'!$AEV$2:$AMA$2,">="&DATE(2025,MONTH(AM$2),1),'TABLERO DIARIO'!$AEV$2:$AMA$2,"<="&EOMONTH(AM$2,0))/COUNTIFS('TABLERO DIARIO'!$AEV$2:$AMA$2,">="&DATE(2025,MONTH(AM$2),1),'TABLERO DIARIO'!$AEV$2:$AMA$2,"<="&EOMONTH(AM$2,0),'TABLERO DIARIO'!$AEV$6:$AMA$6,"<>0"))/1000,"-") -> 38.915675 | AN6: =IFERROR((SUMIFS('TABLERO DIARIO'!$AEV$6:$ASW$6,'TABLERO DIARIO'!$AEV$2:$ASW$2,">="&DATE(2026,MONTH(AN$2),1),'TABLERO DIARIO'!$AEV$2:$ASW$2,"<="&EOMONTH(AN$2,0))/COUNTIFS('TABLERO DIARIO'!$AEV$2:$ASW$2,">="&DATE(2026,MONTH(AN$2),1),'TABLERO DIARIO'!$AEV$2:$ASW$2,"<="&EOMONTH(AN$2,0),'TABLERO DIARIO'!$AEV$6:$ASW$6,"<>0"))/1000,"-") -> 43.097885 | AO6: =IFERROR((SUMIFS('TABLERO DIARIO'!$AEV$6:$ASW$6,'TABLERO DIARIO'!$AEV$2:$ASW$2,">="&DATE(2026,MONTH(AO$2),1),'TABLERO DIARIO'!$AEV$2:$ASW$2,"<="&EOMONTH(AO$2,0))/COUNTIFS('TABLERO DIARIO'!$AEV$2:$ASW$2,">="&DATE(2026,MONTH(AO$2),1),'TABLERO DIARIO'!$AEV$2:$ASW$2,"<="&EOMONTH(AO$2,0),'TABLERO DIARIO'!$AEV$6:$ASW$6,"<>0"))/1000,"-") -> 44.613804 | BA6: =IFERROR(AVERAGE(D6:O6),"-") -> - | BB6: =IFERROR(AVERAGE(P6:AA6),"-") -> - | BC6: =IFERROR(SUMIFS(AB6:AM6,AB6:AM6,"<>0",AB6:AM6,"<>-",AB6:AM6,"<>",AB6:AM6,"<> ")/COUNTIFS(AB6:AM6,"<>0",AB6:AM6,"<>-",AB6:AM6,"<>",AB6:AM6,"<> "),"-") -> 41.688194
B7: PRODUCCIÓN PROM SDF | C7: TN | AC7: =(SUMIFS('TABLERO DIARIO'!$I$6:$ZZ$6,'TABLERO DIARIO'!$I$2:$ZZ$2,">="&DATE(2025,MONTH(AC$2),1),'TABLERO DIARIO'!$I$2:$ZZ$2,"<="&EOMONTH(AC$2,0),'TABLERO DIARIO'!$I$5:$ZZ$5,"SDF")/COUNTIFS('TABLERO DIARIO'!$I$2:$ZZ$2,">="&DATE(2025,MONTH(AC$2),1),'TABLERO DIARIO'!$I$2:$ZZ$2,"<="&EOMONTH(AC$2,0),'TABLERO DIARIO'!$I$5:$ZZ$5,"SDF",'TABLERO DIARIO'!$I$6:$ZZ$6,"<>0"))/1000 -> 32.164625 | AD7: =(SUMIFS('TABLERO DIARIO'!$I$6:$ZZ$6,'TABLERO DIARIO'!$I$2:$ZZ$2,">="&DATE(2025,MONTH(AD$2),1),'TABLERO DIARIO'!$I$2:$ZZ$2,"<="&EOMONTH(AD$2,0),'TABLERO DIARIO'!$I$5:$ZZ$5,"SDF")/COUNTIFS('TABLERO DIARIO'!$I$2:$ZZ$2,">="&DATE(2025,MONTH(AD$2),1),'TABLERO DIARIO'!$I$2:$ZZ$2,"<="&EOMONTH(AD$2,0),'TABLERO DIARIO'!$I$5:$ZZ$5,"SDF",'TABLERO DIARIO'!$I$6:$ZZ$6,"<>0"))/1000 -> 35.487044 | AE7: =(SUMIFS('TABLERO DIARIO'!$I$6:$ZZ$6,'TABLERO DIARIO'!$I$2:$ZZ$2,">="&DATE(2025,MONTH(AE$2),1),'TABLERO DIARIO'!$I$2:$ZZ$2,"<="&EOMONTH(AE$2,0),'TABLERO DIARIO'!$I$5:$ZZ$5,"SDF")/COUNTIFS('TABLERO DIARIO'!$I$2:$ZZ$2,">="&DATE(2025,MONTH(AE$2),1),'TABLERO DIARIO'!$I$2:$ZZ$2,"<="&EOMONTH(AE$2,0),'TABLERO DIARIO'!$I$5:$ZZ$5,"SDF",'TABLERO DIARIO'!$I$6:$ZZ$6,"<>0"))/1000 -> 32.40424 | AF7: =(SUMIFS('TABLERO DIARIO'!$I$6:$ZZ$6,'TABLERO DIARIO'!$I$2:$ZZ$2,">="&DATE(2025,MONTH(AF$2),1),'TABLERO DIARIO'!$I$2:$ZZ$2,"<="&EOMONTH(AF$2,0),'TABLERO DIARIO'!$I$5:$ZZ$5,"SDF")/COUNTIFS('TABLERO DIARIO'!$I$2:$ZZ$2,">="&DATE(2025,MONTH(AF$2),1),'TABLERO DIARIO'!$I$2:$ZZ$2,"<="&EOMONTH(AF$2,0),'TABLERO DIARIO'!$I$5:$ZZ$5,"SDF",'TABLERO DIARIO'!$I$6:$ZZ$6,"<>0"))/1000 -> 41.107675 | AG7: =(SUMIFS('TABLERO DIARIO'!$I$6:$ZZ$6,'TABLERO DIARIO'!$I$2:$ZZ$2,">="&DATE(2025,MONTH(AG$2),1),'TABLERO DIARIO'!$I$2:$ZZ$2,"<="&EOMONTH(AG$2,0),'TABLERO DIARIO'!$I$5:$ZZ$5,"SDF")/COUNTIFS('TABLERO DIARIO'!$I$2:$ZZ$2,">="&DATE(2025,MONTH(AG$2),1),'TABLERO DIARIO'!$I$2:$ZZ$2,"<="&EOMONTH(AG$2,0),'TABLERO DIARIO'!$I$5:$ZZ$5,"SDF",'TABLERO DIARIO'!$I$6:$ZZ$6,"<>0"))/1000 -> 42.126 | AH7: =(SUMIFS('TABLERO DIARIO'!$I$6:$ZZ$6,'TABLERO DIARIO'!$I$2:$ZZ$2,">="&DATE(2025,MONTH(AH$2),1),'TABLERO DIARIO'!$I$2:$ZZ$2,"<="&EOMONTH(AH$2,0),'TABLERO DIARIO'!$I$5:$ZZ$5,"SDF")/COUNTIFS('TABLERO DIARIO'!$I$2:$ZZ$2,">="&DATE(2025,MONTH(AH$2),1),'TABLERO DIARIO'!$I$2:$ZZ$2,"<="&EOMONTH(AH$2,0),'TABLERO DIARIO'!$I$5:$ZZ$5,"SDF",'TABLERO DIARIO'!$I$6:$ZZ$6,"<>0"))/1000 -> 38.04065 | AI7: =IFERROR((SUMIFS('TABLERO DIARIO'!$I$6:$ZZ$6,'TABLERO DIARIO'!$I$2:$ZZ$2,">="&DATE(2025,MONTH(AI$2),1),'TABLERO DIARIO'!$I$2:$ZZ$2,"<="&EOMONTH(AI$2,0),'TABLERO DIARIO'!$I$5:$ZZ$5,"SDF")/COUNTIFS('TABLERO DIARIO'!$I$2:$ZZ$2,">="&DATE(2025,MONTH(AI$2),1),'TABLERO DIARIO'!$I$2:$ZZ$2,"<="&EOMONTH(AI$2,0),'TABLERO DIARIO'!$I$5:$ZZ$5,"SDF",'TABLERO DIARIO'!$I$6:$ZZ$6,"<>0"))/1000,"-") -> - | AJ7: =IFERROR((SUMIFS('TABLERO DIARIO'!$I$6:$ABL$6,'TABLERO DIARIO'!$I$2:$ABL$2,">="&DATE(2025,MONTH(AJ$2),1),'TABLERO DIARIO'!$I$2:$ABL$2,"<="&EOMONTH(AJ$2,0),'TABLERO DIARIO'!$I$5:$ABL$5,"SDF")/COUNTIFS('TABLERO DIARIO'!$I$2:$ABL$2,">="&DATE(2025,MONTH(AJ$2),1),'TABLERO DIARIO'!$I$2:$ABL$2,"<="&EOMONTH(AJ$2,0),'TABLERO DIARIO'!$I$5:$ABL$5,"SDF",'TABLERO DIARIO'!$I$6:$ABL$6,"<>0"))/1000,"-") -> 37.4382 | AK7: =IFERROR((SUMIFS('TABLERO DIARIO'!$I$6:$AEV$6,'TABLERO DIARIO'!$I$2:$AEV$2,">="&DATE(2025,MONTH(AK$2),1),'TABLERO DIARIO'!$I$2:$AEV$2,"<="&EOMONTH(AK$2,0),'TABLERO DIARIO'!$I$5:$AEV$5,"SDF")/(-2+COUNTIFS('TABLERO DIARIO'!$I$2:$AEV$2,">="&DATE(2025,MONTH(AK$2),1),'TABLERO DIARIO'!$I$2:$AEV$2,"<="&EOMONTH(AK$2,0),'TABLERO DIARIO'!$I$5:$AEV$5,"SDF",'TABLERO DIARIO'!$I$6:$AEV$6,"<>0")))/1000,"-") -> 37.536 | AL7: =IFERROR(((SUMIFS('TABLERO DIARIO'!$AEV$7:$ALW$7,'TABLERO DIARIO'!$AEV$2:$ALW$2,">="&DATE(2025,MONTH(AL$2),1),'TABLERO DIARIO'!$AEV$2:$ALW$2,"<="&EOMONTH(AL$2,0),'TABLERO DIARIO'!$AEV$5:$ALW$5,"SDF")+SUMIFS('TABLERO DIARIO'!$AEV$8:$ALW$8,'TABLERO DIARIO'!$AEV$2:$ALW$2,">="&DATE(2025,MONTH(AL$2),1),'TABLERO DIARIO'!$AEV$2:$ALW$2,"<="&EOMONTH(AL$2,0),'TABLERO DIARIO'!$AEV$5:$ALW$5,"SDF"))/(COUNTIFS('TABLERO DIARIO'!$AEV$2:$ALW$2,">="&DATE(2025,MONTH(AL$2),1),'TABLERO DIARIO'!$AEV$2:$ALW$2,"<="&EOMONTH(AL$2,0),'TABLERO DIARIO'!$AEV$5:$ALW$5,"SDF",'TABLERO DIARIO'!$AEV$7:$ALW$7,"<>0")+COUNTIFS('TABLERO DIARIO'!$AEV$2:$ALW$2,">="&DATE(2025,MONTH(AL$2),1),'TABLERO DIARIO'!$AEV$2:$ALW$2,"<="&EOMONTH(AL$2,0),'TABLERO DIARIO'!$AEV$5:$ALW$5,"SDF",'TABLERO DIARIO'!$AEV$8:$ALW$8,"<>0"))*2)/1000,"-") -> 38.43665 | AM7: =IFERROR(((SUMIFS('TABLERO DIARIO'!$AEV$7:$ALW$7,'TABLERO DIARIO'!$AEV$2:$ALW$2,">="&DATE(2025,MONTH(AM$2),1),'TABLERO DIARIO'!$AEV$2:$ALW$2,"<="&EOMONTH(AM$2,0),'TABLERO DIARIO'!$AEV$5:$ALW$5,"SDF")+SUMIFS('TABLERO DIARIO'!$AEV$8:$ALW$8,'TABLERO DIARIO'!$AEV$2:$ALW$2,">="&DATE(2025,MONTH(AM$2),1),'TABLERO DIARIO'!$AEV$2:$ALW$2,"<="&EOMONTH(AM$2,0),'TABLERO DIARIO'!$AEV$5:$ALW$5,"SDF"))/(COUNTIFS('TABLERO DIARIO'!$AEV$2:$ALW$2,">="&DATE(2025,MONTH(AM$2),1),'TABLERO DIARIO'!$AEV$2:$ALW$2,"<="&EOMONTH(AM$2,0),'TABLERO DIARIO'!$AEV$5:$ALW$5,"SDF",'TABLERO DIARIO'!$AEV$7:$ALW$7,"<>0")+COUNTIFS('TABLERO DIARIO'!$AEV$2:$ALW$2,">="&DATE(2025,MONTH(AM$2),1),'TABLERO DIARIO'!$AEV$2:$ALW$2,"<="&EOMONTH(AM$2,0),'TABLERO DIARIO'!$AEV$5:$ALW$5,"SDF",'TABLERO DIARIO'!$AEV$8:$ALW$8,"<>0"))*2)/1000,"-") -> 36.045215 | AN7: =IFERROR(((SUMIFS('TABLERO DIARIO'!$ALW$7:$ASW$7,'TABLERO DIARIO'!$ALW$2:$ASW$2,">="&DATE(2026,MONTH(AN$2),1),'TABLERO DIARIO'!$ALW$2:$ASW$2,"<="&EOMONTH(AN$2,0),'TABLERO DIARIO'!$ALW$5:$ASW$5,"SDF")+SUMIFS('TABLERO DIARIO'!$ALW$8:$ASW$8,'TABLERO DIARIO'!$ALW$2:$ASW$2,">="&DATE(2026,MONTH(AN$2),1),'TABLERO DIARIO'!$ALW$2:$ASW$2,"<="&EOMONTH(AN$2,0),'TABLERO DIARIO'!$ALW$5:$ASW$5,"SDF"))/(COUNTIFS('TABLERO DIARIO'!$ALW$2:$ASW$2,">="&DATE(2026,MONTH(AN$2),1),'TABLERO DIARIO'!$ALW$2:$ASW$2,"<="&EOMONTH(AN$2,0),'TABLERO DIARIO'!$ALW$5:$ASW$5,"SDF",'TABLERO DIARIO'!$ALW$7:$ASW$7,"<>0")+COUNTIFS('TABLERO DIARIO'!$ALW$2:$ASW$2,">="&DATE(2026,MONTH(AN$2),1),'TABLERO DIARIO'!$ALW$2:$ASW$2,"<="&EOMONTH(AN$2,0),'TABLERO DIARIO'!$ALW$5:$ASW$5,"SDF",'TABLERO DIARIO'!$ALW$8:$ASW$8,"<>0"))*2)/1000,"-") -> 39.393464 | AO7: =IFERROR(((SUMIFS('TABLERO DIARIO'!$ALW$7:$ASW$7,'TABLERO DIARIO'!$ALW$2:$ASW$2,">="&DATE(2026,MONTH(AO$2),1),'TABLERO DIARIO'!$ALW$2:$ASW$2,"<="&EOMONTH(AO$2,0),'TABLERO DIARIO'!$ALW$5:$ASW$5,"SDF")+SUMIFS('TABLERO DIARIO'!$ALW$8:$ASW$8,'TABLERO DIARIO'!$ALW$2:$ASW$2,">="&DATE(2026,MONTH(AO$2),1),'TABLERO DIARIO'!$ALW$2:$ASW$2,"<="&EOMONTH(AO$2,0),'TABLERO DIARIO'!$ALW$5:$ASW$5,"SDF"))/(COUNTIFS('TABLERO DIARIO'!$ALW$2:$ASW$2,">="&DATE(2026,MONTH(AO$2),1),'TABLERO DIARIO'!$ALW$2:$ASW$2,"<="&EOMONTH(AO$2,0),'TABLERO DIARIO'!$ALW$5:$ASW$5,"SDF",'TABLERO DIARIO'!$ALW$7:$ASW$7,"<>0")+COUNTIFS('TABLERO DIARIO'!$ALW$2:$ASW$2,">="&DATE(2026,MONTH(AO$2),1),'TABLERO DIARIO'!$ALW$2:$ASW$2,"<="&EOMONTH(AO$2,0),'TABLERO DIARIO'!$ALW$5:$ASW$5,"SDF",'TABLERO DIARIO'!$ALW$8:$ASW$8,"<>0"))*2)/1000,"-") -> 40.433067 | BA7: =IFERROR(AVERAGE(D7:O7),"-") -> - | BB7: =IFERROR(AVERAGE(P7:AA7),"-") -> - | BC7: =IFERROR(SUMIFS(AB7:AM7,AB7:AM7,"<>0",AB7:AM7,"<>-",AB7:AM7,"<>",AB7:AM7,"<> ")/COUNTIFS(AB7:AM7,"<>0",AB7:AM7,"<>-",AB7:AM7,"<>",AB7:AM7,"<> "),"-") -> 37.07863
B8: PRODUCCIÓN PROM LV | C8: TN | D8: - | E8: - | F8: - | G8: - | H8: - | I8: - | J8: - | K8: - | L8: - | M8: - | N8: - | P8: - | Q8: - | R8: - | S8: - | T8: - | U8: - | V8: - | W8: - | X8: - | Y8: - | Z8: - | AA8: - | AB8: - | AC8: 44.6 | AD8: 42.1 | AE8: 45.9 | AF8: 45.8 | AG8: =(SUMIFS('TABLERO DIARIO'!$I$6:$ZZ$6,'TABLERO DIARIO'!$I$2:$ZZ$2,">="&DATE(2025,MONTH(AG$2),1),'TABLERO DIARIO'!$I$2:$ZZ$2,"<="&EOMONTH(AG$2,0),'TABLERO DIARIO'!$I$5:$ZZ$5,"LV")/COUNTIFS('TABLERO DIARIO'!$I$2:$ZZ$2,">="&DATE(2025,MONTH(AG$2),1),'TABLERO DIARIO'!$I$2:$ZZ$2,"<="&EOMONTH(AG$2,0),'TABLERO DIARIO'!$I$5:$ZZ$5,"LV",'TABLERO DIARIO'!$I$6:$ZZ$6,"<>0"))/1000 -> 43.013624 | AH8: =(SUMIFS('TABLERO DIARIO'!$I$6:$ZZ$6,'TABLERO DIARIO'!$I$2:$ZZ$2,">="&DATE(2025,MONTH(AH$2),1),'TABLERO DIARIO'!$I$2:$ZZ$2,"<="&EOMONTH(AH$2,0),'TABLERO DIARIO'!$I$5:$ZZ$5,"LV")/COUNTIFS('TABLERO DIARIO'!$I$2:$ZZ$2,">="&DATE(2025,MONTH(AH$2),1),'TABLERO DIARIO'!$I$2:$ZZ$2,"<="&EOMONTH(AH$2,0),'TABLERO DIARIO'!$I$5:$ZZ$5,"LV",'TABLERO DIARIO'!$I$6:$ZZ$6,"<>0"))/1000 -> 43.9681 | AI8: =IFERROR((SUMIFS('TABLERO DIARIO'!$I$6:$ZZ$6,'TABLERO DIARIO'!$I$2:$ZZ$2,">="&DATE(2025,MONTH(AI$2),1),'TABLERO DIARIO'!$I$2:$ZZ$2,"<="&EOMONTH(AI$2,0),'TABLERO DIARIO'!$I$5:$ZZ$5,"LV")/COUNTIFS('TABLERO DIARIO'!$I$2:$ZZ$2,">="&DATE(2025,MONTH(AI$2),1),'TABLERO DIARIO'!$I$2:$ZZ$2,"<="&EOMONTH(AI$2,0),'TABLERO DIARIO'!$I$5:$ZZ$5,"LV",'TABLERO DIARIO'!$I$6:$ZZ$6,"<>0"))/1000,"-") -> 45.099248 | AJ8: =IFERROR((SUMIFS('TABLERO DIARIO'!$I$6:$ABL$6,'TABLERO DIARIO'!$I$2:$ABL$2,">="&DATE(2025,MONTH(AJ$2),1),'TABLERO DIARIO'!$I$2:$ABL$2,"<="&EOMONTH(AJ$2,0),'TABLERO DIARIO'!$I$5:$ABL$5,"LV")/COUNTIFS('TABLERO DIARIO'!$I$2:$ABL$2,">="&DATE(2025,MONTH(AJ$2),1),'TABLERO DIARIO'!$I$2:$ABL$2,"<="&EOMONTH(AJ$2,0),'TABLERO DIARIO'!$I$5:$ABL$5,"LV",'TABLERO DIARIO'!$I$6:$ABL$6,"<>0"))/1000,"-") -> 42.47495 | AK8: =IFERROR((SUMIFS('TABLERO DIARIO'!$I$6:$AEV$6,'TABLERO DIARIO'!$I$2:$AEV$2,">="&DATE(2025,MONTH(AK$2),1),'TABLERO DIARIO'!$I$2:$AEV$2,"<="&EOMONTH(AK$2,0),'TABLERO DIARIO'!$I$5:$AEV$5,"LV")/COUNTIFS('TABLERO DIARIO'!$I$2:$AEV$2,">="&DATE(2025,MONTH(AK$2),1),'TABLERO DIARIO'!$I$2:$AEV$2,"<="&EOMONTH(AK$2,0),'TABLERO DIARIO'!$I$5:$AEV$5,"LV",'TABLERO DIARIO'!$I$6:$AEV$6,"<>0"))/1000,"-") -> 42.261191 | AL8: =IFERROR((SUMIFS('TABLERO DIARIO'!$AEV$6:$AMA$6,'TABLERO DIARIO'!$AEV$2:$AMA$2,">="&DATE(2025,MONTH(AL$2),1),'TABLERO DIARIO'!$AEV$2:$AMA$2,"<="&EOMONTH(AL$2,0),'TABLERO DIARIO'!$AEV$5:$AMA$5,"LV")/COUNTIFS('TABLERO DIARIO'!$AEV$2:$AMA$2,">="&DATE(2025,MONTH(AL$2),1),'TABLERO DIARIO'!$AEV$2:$AMA$2,"<="&EOMONTH(AL$2,0),'TABLERO DIARIO'!$AEV$5:$AMA$5,"LV",'TABLERO DIARIO'!$AEV$6:$AMA$6,"<>0"))/1000,"-") -> 43.738321 | AM8: =IFERROR((SUMIFS('TABLERO DIARIO'!$AEV$6:$AMA$6,'TABLERO DIARIO'!$AEV$2:$AMA$2,">="&DATE(2025,MONTH(AM$2),1),'TABLERO DIARIO'!$AEV$2:$AMA$2,"<="&EOMONTH(AM$2,0),'TABLERO DIARIO'!$AEV$5:$AMA$5,"LV")/COUNTIFS('TABLERO DIARIO'!$AEV$2:$AMA$2,">="&DATE(2025,MONTH(AM$2),1),'TABLERO DIARIO'!$AEV$2:$AMA$2,"<="&EOMONTH(AM$2,0),'TABLERO DIARIO'!$AEV$5:$AMA$5,"LV",'TABLERO DIARIO'!$AEV$6:$AMA$6,"<>0"))/1000,"-") -> 40.730714 | AN8: =IFERROR((SUMIFS('TABLERO DIARIO'!$ALW$6:$ASW$6,'TABLERO DIARIO'!$ALW$2:$ASW$2,">="&DATE(2026,MONTH(AN$2),1),'TABLERO DIARIO'!$ALW$2:$ASW$2,"<="&EOMONTH(AN$2,0),'TABLERO DIARIO'!$ALW$5:$ASW$5,"LV")/COUNTIFS('TABLERO DIARIO'!$ALW$2:$ASW$2,">="&DATE(2026,MONTH(AN$2),1),'TABLERO DIARIO'!$ALW$2:$ASW$2,"<="&EOMONTH(AN$2,0),'TABLERO DIARIO'!$ALW$5:$ASW$5,"LV",'TABLERO DIARIO'!$ALW$6:$ASW$6,"<>0"))/1000,"-") -> 44.15629 | AO8: =IFERROR((SUMIFS('TABLERO DIARIO'!$ALW$6:$ASW$6,'TABLERO DIARIO'!$ALW$2:$ASW$2,">="&DATE(2026,MONTH(AO$2),1),'TABLERO DIARIO'!$ALW$2:$ASW$2,"<="&EOMONTH(AO$2,0),'TABLERO DIARIO'!$ALW$5:$ASW$5,"LV")/COUNTIFS('TABLERO DIARIO'!$ALW$2:$ASW$2,">="&DATE(2026,MONTH(AO$2),1),'TABLERO DIARIO'!$ALW$2:$ASW$2,"<="&EOMONTH(AO$2,0),'TABLERO DIARIO'!$ALW$5:$ASW$5,"LV",'TABLERO DIARIO'!$ALW$6:$ASW$6,"<>0"))/1000,"-") -> 46.007383 | BA8: =IFERROR(AVERAGE(D8:O8),"-") -> - | BB8: =IFERROR(AVERAGE(P8:AA8),"-") -> - | BC8: =IFERROR(SUMIFS(AB8:AM8,AB8:AM8,"<>0",AB8:AM8,"<>-",AB8:AM8,"<>",AB8:AM8,"<> ")/COUNTIFS(AB8:AM8,"<>0",AB8:AM8,"<>-",AB8:AM8,"<>",AB8:AM8,"<> "),"-") -> 43.607832
B9: EFICIENCIA | C9: % | D9: 0.69 | E9: 0.75 | F9: 0.77 | G9: 0.83 | H9: 0.84 | I9: 0.78 | J9: 0.76 | K9: 0.78 | L9: 0.75 | M9: 0.76 | N9: 0.79 | O9: 0.71 | P9: 0.72 | Q9: 0.61 | R9: 0.68 | S9: 0.76 | T9: 0.75 | U9: 0.77 | V9: 0.7 | W9: 0.74 | X9: 0.66 | Y9: 0.73 | Z9: 0.74 | AA9: 0.8 | AB9: 0.8 | AC9: 0.8 | AD9: 0.789 | AE9: 0.808 | AF9: 0.821 | AG9: 0.816 | AH9: 0.793 | AI9: 0.807 | AJ9: 0.76 | AK9: 0.76 | AL9: 0.787 | AM9: 0.764 | AN9: 0.791 | AO9: 0.832 | BA9: =IFERROR(AVERAGE(D9:O9),"-") -> 0.7675 | BB9: =IFERROR(AVERAGE(P9:AA9),"-") -> 0.72166667 | BC9: =IFERROR(SUMIFS(AB9:AM9,AB9:AM9,"<>0",AB9:AM9,"<>-",AB9:AM9,"<>",AB9:AM9,"<> ")/COUNTIFS(AB9:AM9,"<>0",AB9:AM9,"<>-",AB9:AM9,"<>",AB9:AM9,"<> "),"-") -> 0.79208333
B10: MERMA | C10: % | D10: 0.029 | E10: 0.036 | F10: 0.033 | G10: 0.036 | H10: 0.036 | I10: 0.031 | J10: 0.032 | K10: 0.037 | L10: 0.036 | M10: 0.036 | N10: 0.037 | O10: 0.039 | P10: 0.035 | Q10: 0.035 | R10: 0.032 | S10: 0.028 | T10: 0.023 | U10: 0.022 | V10: 0.018 | W10: 0.019 | X10: 0.02 | Y10: 0.02 | Z10: 0.018 | AA10: 0.021 | AB10: 0.024 | AC10: 0.023 | AD10: 0.019 | AE10: =SUM(AE11:AE15) -> 0.0196 | AF10: =SUM(AF11:AF15) -> 0.019 | AG10: =SUM(AG11:AG15) -> 0.0256 | AH10: =SUM(AH11:AH15) -> 0.02292 | AI10: =SUM(AI11:AI15) -> 0.02111 | AJ10: 0.02291 | AK10: 0.02664 | AL10: =+SUM(AL11:AL15) -> 0.02571 | AM10: 0.02249 | AN10: 0.02126 | AO10: 0.02203 | BA10: =IFERROR(AVERAGE(D10:O10),"-") -> 0.034833333 | BB10: =IFERROR(AVERAGE(P10:AA10),"-") -> 0.02425 | BC10: =IFERROR(SUMIFS(AB10:AM10,AB10:AM10,"<>0",AB10:AM10,"<>-",AB10:AM10,"<>",AB10:AM10,"<> ")/COUNTIFS(AB10:AM10,"<>0",AB10:AM10,"<>-",AB10:AM10,"<>",AB10:AM10,"<> "),"-") -> 0.022665
B11: DECOMISO | C11: % | G11: 0.016 | H11: 0.014 | I11: 0.014 | J11: 0.015 | K11: 0.014 | L11: 0.016 | M11: 0.016 | N11: 0.017 | O11: 0.018 | P11: 0.015 | Q11: 0.018 | R11: 0.016 | S11: 0.014 | T11: 0.013 | U11: 0.008 | V11: 0.005 | W11: 0.004 | X11: 0.005 | Y11: 0.006 | Z11: 0.007 | AA11: 0.006 | AB11: 0.7% | AC11: 0.7% | AD11: 0.007 | AE11: 0.0068 | AF11: 0.0069 | AG11: 0.00654 | AH11: =+AH16 -> 0.00742 | AI11: 0.00756 | AJ11: 0.00755 | AK11: 0.0085 | AL11: 0.0089 | AM11: 0.00987 | AN11: 0.0084 | AO11: 0.00779 | BA11: =IFERROR(AVERAGE(D11:O11),"-") -> 0.015555556 | BB11: =IFERROR(AVERAGE(P11:AA11),"-") -> 0.00975 | BC11: =IFERROR(SUMIFS(AB11:AM11,AB11:AM11,"<>0",AB11:AM11,"<>-",AB11:AM11,"<>",AB11:AM11,"<> ")/COUNTIFS(AB11:AM11,"<>0",AB11:AM11,"<>-",AB11:AM11,"<>",AB11:AM11,"<> "),"-") -> 0.00642
B12: PÉRDIDA POR PESO | C12: % | G12: 0.004 | H12: 0.005 | I12: 0.004 | J12: 0.004 | K12: 0.004 | L12: 0.006 | M12: 0.007 | N12: 0.004 | O12: 0.006 | P12: 0.006 | Q12: 0.007 | R12: 0.002 | S12: 0 | T12: 0.001 | U12: 0.001 | V12: 0.003 | W12: 0.002 | X12: 0.002 | Y12: 0.001 | Z12: 0.001 | AA12: 0.001 | AB12: 0.5% | AC12: 0.3% | AD12: 0.002 | AE12: 0.0005 | AF12: 0.0024 | AG12: 0.0018 | AH12: 0.0039 | AI12: 0.0009 | AJ12: 0.0023 | AK12: 0.0048 | AL12: 0.0034 | AM12: 0.0027 | AN12: 0.0039 | BA12: =IFERROR(AVERAGE(D12:O12),"-") -> 0.0048888889 | BB12: =IFERROR(AVERAGE(P12:AA12),"-") -> 0.00225 | BC12: =IFERROR(SUMIFS(AB12:AM12,AB12:AM12,"<>0",AB12:AM12,"<>-",AB12:AM12,"<>",AB12:AM12,"<> ")/COUNTIFS(AB12:AM12,"<>0",AB12:AM12,"<>-",AB12:AM12,"<>",AB12:AM12,"<> "),"-") -> 0.0020583333
B13: PÉRDIDA POR FRÍO | C13: % | G13: 0.003 | H13: 0.003 | I13: 0.004 | J13: 0.004 | K13: 0.002 | L13: 0.004 | M13: 0.003 | N13: 0.003 | O13: 0.004 | P13: 0.004 | Q13: 0.003 | R13: 0.003 | S13: 0.003 | T13: 0.003 | U13: 0.004 | V13: 0.004 | W13: 0.002 | X13: 0.002 | Y13: 0.003 | Z13: 0.003 | AA13: 0.003 | AB13: 0.2% | AC13: 0.3% | AD13: 0.003 | AE13: 0.0023 | AF13: 0.0014 | AG13: 0.001 | AH13: 0.0026 | AI13: 0.0019 | AJ13: 0.0022 | AK13: 0.0034 | AL13: 0.0018 | AM13: 0.0019 | AN13: 0.0018 | BA13: =IFERROR(AVERAGE(D13:O13),"-") -> 0.0033333333 | BB13: =IFERROR(AVERAGE(P13:AA13),"-") -> 0.0030833333 | BC13: =IFERROR(SUMIFS(AB13:AM13,AB13:AM13,"<>0",AB13:AM13,"<>-",AB13:AM13,"<>",AB13:AM13,"<> ")/COUNTIFS(AB13:AM13,"<>0",AB13:AM13,"<>-",AB13:AM13,"<>",AB13:AM13,"<> "),"-") -> 0.0017916667
B14: SIN EXPLICACIÓN | C14: % | G14: 0.012 | H14: 0.014 | I14: 0.01 | J14: 0.01 | K14: 0.015 | L14: 0.01 | M14: 0.01 | N14: 0.012 | O14: 0.011 | P14: 0.01 | Q14: 0.007 | R14: 0.011 | S14: 0.011 | T14: 0.006 | U14: 0.009 | V14: 0.006 | W14: 0.011 | X14: 0.011 | Y14: 0.01 | Z14: 0.007 | AA14: 0.011 | AB14: 1.0% | AC14: 1.0% | AD14: 0.007 | AE14: 0.009 | AF14: 0.009 | AG14: 0.0117 | AH14: 0.005 | AI14: 0.0071 | AJ14: 0.0075 | AK14: 0.0059 | AL14: 0.00766 | AM14: 0.0115 | AN14: 0.01126 | BA14: =IFERROR(AVERAGE(D14:O14),"-") -> 0.011555556 | BB14: =IFERROR(AVERAGE(P14:AA14),"-") -> 0.0091666667 | BC14: =IFERROR(SUMIFS(AB14:AM14,AB14:AM14,"<>0",AB14:AM14,"<>-",AB14:AM14,"<>",AB14:AM14,"<> ")/COUNTIFS(AB14:AM14,"<>0",AB14:AM14,"<>-",AB14:AM14,"<>",AB14:AM14,"<> "),"-") -> 0.00678
B15: HIELO | C15: % | AE15: 0.001 | AF15: -0.0007 | AG15: 0.00456 | AH15: 0.004 | AI15: 0.00365 | AJ15: 0.00333 | AK15: 0.004 | AL15: 0.00395 | AM15: -0.0038 | AN15: -0.00413 | AO15: -0.00043 | BA15: =IFERROR(AVERAGE(D15:O15),"-") -> - | BB15: =IFERROR(AVERAGE(P15:AA15),"-") -> - | BC15: =IFERROR(SUMIFS(AB15:AM15,AB15:AM15,"<>0",AB15:AM15,"<>-",AB15:AM15,"<>",AB15:AM15,"<> ")/COUNTIFS(AB15:AM15,"<>0",AB15:AM15,"<>-",AB15:AM15,"<>",AB15:AM15,"<> "),"-") -> 0.0022211111
B16: DECOMISO | C16: % | D16: 0.01 | E16: 0.018 | F16: 0.018 | G16: 0.016 | H16: 0.014 | I16: 0.014 | J16: 0.015 | K16: 0.015 | L16: 0.016 | M16: 0.016 | N16: 0.017 | O16: 0.018 | P16: 0.015 | Q16: 0.018 | R16: 0.016 | S16: 0.014 | T16: 0.013 | U16: 0.008 | V16: 0.005 | W16: 0.004 | X16: 0.005 | Y16: 0.006 | Z16: 0.007 | AA16: 0.006 | AB16: 0.007 | AC16: 0.007 | AD16: 0.007 | AE16: 0.0068 | AF16: 0.0069 | AG16: 0.00654 | AH16: 0.00742 | AI16: 0.00756 | AJ16: 0.00755 | AK16: 0.0085 | AL16: =+SUM(AL17:AL22) -> 0.0089 | AM16: =+SUM(AM17:AM22) -> 0.00985 | AN16: =+SUM(AN17:AN22) -> 0.0084 | AO16: =+SUM(AO17:AO22) -> 0.00778 | BA16: =IFERROR(AVERAGE(D16:O16),"-") -> 0.015583333 | BB16: =IFERROR(AVERAGE(P16:AA16),"-") -> 0.00975 | BC16: =IFERROR(SUMIFS(AB16:AM16,AB16:AM16,"<>0",AB16:AM16,"<>-",AB16:AM16,"<>",AB16:AM16,"<> ")/COUNTIFS(AB16:AM16,"<>0",AB16:AM16,"<>-",AB16:AM16,"<>",AB16:AM16,"<> "),"-") -> 0.007585
B17: FORMAX OPERACIÓN | C17: % | D17: 0.01 | E17: 0.01 | F17: 0.01 | G17: 0.01 | H17: 0.01 | I17: 0.009 | J17: 0.01 | K17: 0.011 | L17: 0.011 | M17: 0.011 | N17: 0.01 | O17: 0.01 | P17: 0.012 | Q17: 0.014 | R17: 0.012 | S17: 0.01 | T17: 0.005 | U17: 0.006 | V17: 0.005 | W17: 0.003 | X17: 0.004 | Y17: 0.005 | Z17: 0.005 | AA17: 0.005 | AB17: 0.006 | AC17: 0.006 | AD17: 0.00596 | AE17: 0.0055 | AF17: 0.00556 | AG17: 0.00498 | AH17: 0.00548 | AI17: 0.00487 | AJ17: 0.0055 | AK17: 0.00412 | AL17: 0.00563 | AM17: 0.00581 | AN17: 0.00506 | AO17: 0.0045 | BA17: =IFERROR(AVERAGE(D17:O17),"-") -> 0.010166667 | BB17: =IFERROR(AVERAGE(P17:AA17),"-") -> 0.0071666667 | BC17: =IFERROR(SUMIFS(AB17:AM17,AB17:AM17,"<>0",AB17:AM17,"<>-",AB17:AM17,"<>",AB17:AM17,"<> ")/COUNTIFS(AB17:AM17,"<>0",AB17:AM17,"<>-",AB17:AM17,"<>",AB17:AM17,"<> "),"-") -> 0.0054508333
B18: DURO | C18: % | D18: 0 | E18: 0.005 | F18: 0.005 | G18: 0.003 | H18: 0.002 | I18: 0.001 | J18: 0.002 | K18: 0.002 | L18: 0.003 | M18: 0.002 | N18: 0.005 | O18: 0.007 | P18: 0.002 | Q18: 0.003 | R18: 0.003 | S18: 0.002 | T18: 0.001 | U18: 0.001 | V18: 0 | W18: 0 | X18: 0 | Y18: 0 | Z18: 0 | AA18: 0 | AB18: 0 | AC18: 0 | AD18: 0 | AE18: 0 | AF18: 0 | AG18: 0 | AH18: 0 | AI18: 0 | AJ18: 0 | AK18: 0 | AL18: 0 | AM18: 0 | AN18: 0 | AO18: 0 | BA18: =IFERROR(AVERAGE(D18:O18),"-") -> 0.0030833333 | BB18: =IFERROR(AVERAGE(P18:AA18),"-") -> 0.001 | BC18: =IFERROR(SUMIFS(AB18:AM18,AB18:AM18,"<>0",AB18:AM18,"<>-",AB18:AM18,"<>",AB18:AM18,"<> ")/COUNTIFS(AB18:AM18,"<>0",AB18:AM18,"<>-",AB18:AM18,"<>",AB18:AM18,"<> "),"-") -> -
B19: PISO | C19: % | D19: 0 | E19: 0.002 | F19: 0.002 | G19: 0.001 | H19: 0.001 | I19: 0.001 | J19: 0.001 | K19: 0.001 | L19: 0.001 | M19: 0.001 | N19: 0 | O19: 0 | P19: 0 | Q19: 0.001 | R19: 0 | S19: 0 | T19: 0 | U19: 0.001 | V19: 0 | W19: 0.001 | X19: 0 | Y19: 0.001 | Z19: 0 | AA19: 0.001 | AB19: 0 | AC19: 0.001 | AD19: 0.00052 | AE19: 0.00048 | AF19: 0.00065 | AG19: 0.00031 | AH19: 0.00083 | AI19: 0.00153 | AJ19: 0.00092 | AK19: 0.00074 | AL19: 0.00106 | AM19: 0.00091 | AN19: 0.00087 | AO19: 0.0008 | BA19: =IFERROR(AVERAGE(D19:O19),"-") -> 0.00091666667 | BB19: =IFERROR(AVERAGE(P19:AA19),"-") -> 0.00041666667 | BC19: =IFERROR(SUMIFS(AB19:AM19,AB19:AM19,"<>0",AB19:AM19,"<>-",AB19:AM19,"<>",AB19:AM19,"<> ")/COUNTIFS(AB19:AM19,"<>0",AB19:AM19,"<>-",AB19:AM19,"<>",AB19:AM19,"<> "),"-") -> 0.00081363636
B20: BARRIDO HIGIENE | C20: % | D20: 0 | E20: 0.001 | F20: 0.001 | G20: 0.001 | H20: 0.001 | I20: 0.001 | J20: 0.001 | K20: 0.001 | L20: 0.001 | M20: 0.001 | N20: 0.001 | O20: 0.001 | P20: 0.001 | Q20: 0.001 | R20: 0.001 | S20: 0.001 | T20: 0.001 | U20: 0.001 | V20: 0 | W20: 0.001 | X20: 0.001 | Y20: 0.001 | Z20: 0.001 | AA20: 0.001 | AB20: 0.001 | AC20: 0.001 | AD20: 0.00075 | AE20: 0.00076 | AF20: 0.0007 | AG20: 0.00076 | AH20: 0.00079 | AI20: 0.00106 | AJ20: 0.00098 | AK20: 0.00106 | AL20: 0.00106 | AM20: 0.00104 | AN20: 0.00105 | AO20: 0.00122 | BA20: =IFERROR(AVERAGE(D20:O20),"-") -> 0.00091666667 | BB20: =IFERROR(AVERAGE(P20:AA20),"-") -> 0.00091666667 | BC20: =IFERROR(SUMIFS(AB20:AM20,AB20:AM20,"<>0",AB20:AM20,"<>-",AB20:AM20,"<>",AB20:AM20,"<> ")/COUNTIFS(AB20:AM20,"<>0",AB20:AM20,"<>-",AB20:AM20,"<>",AB20:AM20,"<> "),"-") -> 0.00091333333
B21: SOJA | C21: % | D21: 0 | E21: 0.001 | F21: 0.001 | G21: 0.001 | H21: 0.001 | I21: 0.002 | J21: 0.001 | K21: 0.001 | L21: 0.001 | M21: 0.002 | N21: 0 | O21: 0 | P21: 0.001 | Q21: 0.001 | R21: 0 | S21: 0 | T21: 0.001 | U21: 0 | V21: 0 | W21: 0 | X21: 0 | Y21: 0 | Z21: 0 | AA21: 0 | AB21: 0 | AC21: 0 | AD21: 0.0001 | AE21: 7e-05 | AF21: 3e-05 | AG21: 8e-05 | AH21: 0.00032 | AI21: 0.00011 | AJ21: 0.00013 | AK21: 7e-05 | AL21: 0.00022 | AM21: 0.00012 | AN21: 0.00036 | AO21: 0.00012 | BA21: =IFERROR(AVERAGE(D21:O21),"-") -> 0.00091666667 | BB21: =IFERROR(AVERAGE(P21:AA21),"-") -> 0.00025 | BC21: =IFERROR(SUMIFS(AB21:AM21,AB21:AM21,"<>0",AB21:AM21,"<>-",AB21:AM21,"<>",AB21:AM21,"<> ")/COUNTIFS(AB21:AM21,"<>0",AB21:AM21,"<>-",AB21:AM21,"<>",AB21:AM21,"<> "),"-") -> 0.000125
B22: OTRO | C22: % | D22: - | E22: - | F22: - | G22: - | H22: - | I22: - | J22: - | K22: - | L22: - | M22: - | N22: - | O22: - | P22: - | Q22: - | R22: - | S22: - | T22: 0.004 | U22: - | V22: - | W22: - | X22: - | Y22: - | Z22: - | AA22: - | AB22: 0.1% | AC22: - | AD22: - | AE22: - | AF22: - | AG22: - | AH22: - | AI22: - | AJ22: 1e-05 | AK22: 0.00251 | AL22: 0.00093 | AM22: 0.00197 | AN22: 0.00106 | AO22: 0.00114 | BA22: =IFERROR(AVERAGE(D22:O22),"-") -> - | BB22: =IFERROR(AVERAGE(P22:AA22),"-") -> 0.004 | BC22: =IFERROR(SUMIFS(AB22:AM22,AB22:AM22,"<>0",AB22:AM22,"<>-",AB22:AM22,"<>",AB22:AM22,"<> ")/COUNTIFS(AB22:AM22,"<>0",AB22:AM22,"<>-",AB22:AM22,"<>",AB22:AM22,"<> "),"-") -> 0.001084
B23: DESVÍO COSTO STD VS REAL - SIN REP | C23: % | D23: - | E23: - | F23: - | G23: - | H23: - | I23: - | J23: - | K23: - | L23: - | M23: - | N23: - | O23: - | S23: 0.019 | T23: 0.004 | U23: 0.018 | V23: 0.011 | W23: 0.03 | X23: 0.048 | Y23: 0.064 | Z23: 0.069 | AA23: 0.033 | AB23: 0.038 | AC23: 0.029 | AD23: 0.028 | AE23: -0.002 | AF23: 0.013 | AG23: 0.01 | AH23: -0.009 | AI23: -0.01 | AJ23: 0.052 | AK23: 0.036 | AL23: 0.027 | AM23: 0.023 | AN23: 0.006 | AO23: -0.016 | BA23: =IFERROR(AVERAGE(D23:O23),"-") -> - | BB23: =IFERROR(AVERAGE(P23:AA23),"-") -> 0.032888889 | BC23: =IFERROR(SUMIFS(AB23:AM23,AB23:AM23,"<>0",AB23:AM23,"<>-",AB23:AM23,"<>",AB23:AM23,"<> ")/COUNTIFS(AB23:AM23,"<>0",AB23:AM23,"<>-",AB23:AM23,"<>",AB23:AM23,"<> "),"-") -> 0.019583333
B24: DESVÍO COSTO STD VS REAL - SIN REP | C24: MILL | D24: - | E24: - | F24: - | G24: - | H24: - | I24: - | J24: - | K24: - | L24: - | M24: - | N24: - | O24: - | S24: 33.17 | T24: 8.06 | U24: 32.29 | V24: 23.74 | W24: 75.57 | X24: 129.09 | Y24: 204.13 | Z24: 234.88 | AA24: 121.72 | AB24: 143.61 | AC24: 114.05 | AD24: 111.52 | AE24: -7.41 | AF24: 51.75 | AG24: 36.376 | AH24: -41.693 | AI24: -37.929 | AJ24: 229.319 | AK24: 177.918 | AL24: 136.571 | AM24: 142.38064 | AN24: 36.638508 | AO24: -92.70639 | BA24: =IFERROR(AVERAGE(D24:O24),"-") -> - | BB24: =IFERROR(AVERAGE(P24:AA24),"-") -> 95.85 | BC24: =IFERROR(SUMIFS(AB24:AM24,AB24:AM24,"<>0",AB24:AM24,"<>-",AB24:AM24,"<>",AB24:AM24,"<> ")/COUNTIFS(AB24:AM24,"<>0",AB24:AM24,"<>-",AB24:AM24,"<>",AB24:AM24,"<> "),"-") -> 88.038554
B25: DESVÍO COSTO STD VS REAL - CON REP | C25: % | D25: - | E25: - | F25: - | G25: - | H25: - | I25: - | J25: - | K25: - | L25: - | M25: - | N25: - | O25: - | P25: 0.07 | Q25: 0.035 | R25: 0.06 | S25: 0.051 | T25: 0.029 | U25: 0.023 | V25: 0.014 | W25: 0.032 | X25: 0.052 | Y25: 0.07 | Z25: 0.073 | AA25: 0.035 | AB25: 0.039 | AC25: 0.031 | AD25: 0.03 | AE25: -0.001 | AF25: 0.016 | AG25: 0.016 | AH25: 0 | AI25: 0.013 | AJ25: 0.06 | AK25: 0.04 | AL25: 0.036 | AM25: 0.022 | AN25: 0.01 | AO25: -0.005 | BA25: =IFERROR(AVERAGE(D25:O25),"-") -> - | BB25: =IFERROR(AVERAGE(P25:AA25),"-") -> 0.045333333 | BC25: =IFERROR(SUMIFS(AB25:AM25,AB25:AM25,"<>0",AB25:AM25,"<>-",AB25:AM25,"<>",AB25:AM25,"<> ")/COUNTIFS(AB25:AM25,"<>0",AB25:AM25,"<>-",AB25:AM25,"<>",AB25:AM25,"<> "),"-") -> 0.027454545
B26: DESVÍO COSTO STD VS REAL - CON REP | C26: MILL | D26: - | E26: - | F26: - | G26: - | H26: - | I26: - | J26: - | K26: - | L26: - | M26: - | N26: - | O26: - | P26: 138.98 | Q26: 61.14 | R26: 100.2 | S26: 92.16 | T26: 54.54 | U26: 41.63 | V26: 32.12 | W26: 79.38 | X26: 138.99 | Y26: 224.09 | Z26: 247.78 | AA26: 128.75 | AB26: 148.11 | AC26: 124.63 | AD26: 126.92 | AE26: -3.51 | AF26: 62.03 | AG26: 56.835 | AH26: 0.762335 | AI26: 49.221 | AJ26: 260.723 | AK26: 196.9 | AL26: 183.329 | AM26: 135.9646 | AN26: 61.89194 | AO26: -31.568728 | BA26: =IFERROR(AVERAGE(D26:O26),"-") -> - | BB26: =IFERROR(AVERAGE(P26:AA26),"-") -> 111.64667 | BC26: =IFERROR(SUMIFS(AB26:AM26,AB26:AM26,"<>0",AB26:AM26,"<>-",AB26:AM26,"<>",AB26:AM26,"<> ")/COUNTIFS(AB26:AM26,"<>0",AB26:AM26,"<>-",AB26:AM26,"<>",AB26:AM26,"<> "),"-") -> 111.82624
B27: COSTO PRODUCCIÓN POR KG | C27: $ | AG27: 4428.73 | AH27: 4290.93 | AI27: 4822.09 | AJ27: 5128.77 | AK27: 5383 | AL27: 5555.75 | AM27: 6209.8565 | AN27: 6327.68 | AO27: 6135.5
B28: CONSUMO CARNE POR KG | C28: $ | AG28: 4038.63 | AH28: 3884.73 | AI28: 4375.53 | AJ28: 4723.68 | AK28: 4960.1 | AL28: 5107.69 | AM28: 5836.2225 | AN28: 5918.98 | AO28: 5686.16
B29: CONSUMO ADITIVOS POR KG | C29: $ | AG29: 108.62 | AH29: 103.18 | AI29: 95.39 | AJ29: 113.44 | AK29: 124.11 | AL29: 122.12 | AM29: 109.54415 | AN29: 113.94 | AO29: 108.3
B30: CONSUMOS EMBALAJE POR KG | C30: $ | AG30: 255.13 | AH30: 267.63 | AI30: 256.79 | AJ30: 272.25 | AK30: 276.28 | AL30: 274.63 | AM30: 267.75448 | AN30: 265.44 | AO30: 274.12
B31: CONSUMO HIELO POR KG S, TH Y J | C31: $ | AG31: 26.2 | AH31: 35.5 | AI31: 34.41 | AJ31: 32.88 | AK31: 27.88 | AL31: 26.76 | AM31: 26.099609 | AN31: 23.68 | AO31: 29.2
B32: CONSUMO REPROCESO POR KG | C32: $ | AG32: 185.05 | AH32: 301.84 | AI32: 934.57 | AJ32: 154.68 | AK32: 133.34 | AL32: 315.54 | AM32: -36.637227 | AN32: 159.41 | AO32: 483.24
B33: CONSUMO REENVASADO POR KG DE REENVASADO | C33: $ | AG33: 400.35 | AH33: 377.8 | AI33: 384.69 | AJ33: 360.65 | AK33: 305.42 | AL33: 433.43 | AM33: 357.01957 | AN33: 395.02 | AO33: 385.66
B34: DESVÍO INGRESO A PICADORA | C34: UNI | D34: 0.02 | E34: 0.013 | F34: 0.015 | G34: 0.017 | H34: 0.013 | I34: 0.014 | J34: 0.045 | K34: 0.031 | L34: 0.031 | M34: 0.016 | N34: 0.012 | O34: 0.013 | P34: 0.015 | Q34: 0.026 | R34: 0.028 | S34: 0.006 | T34: 0.013 | U34: 0.005 | V34: 0.008 | W34: 0.013 | X34: 0.02 | Y34: 0.033 | Z34: 0.022 | AA34: - | AB34: - | AC34: - | AD34: 180 | AE34: 173 | AF34: 280 | AG34: 27 | AH34: =172+48 -> 220 | AI34: 9 | AJ34: 96 | AK34: 40 | AL34: 19 | AM34: 101 | AN34: 50 | BA34: =IFERROR(AVERAGE(D34:O34),"-") -> 0.02 | BB34: =IFERROR(AVERAGE(P34:AA34),"-") -> 0.017181818 | BC34: =IFERROR(SUMIFS(AB34:AM34,AB34:AM34,"<>0",AB34:AM34,"<>-",AB34:AM34,"<>",AB34:AM34,"<> ")/COUNTIFS(AB34:AM34,"<>0",AB34:AM34,"<>-",AB34:AM34,"<>",AB34:AM34,"<> "),"-") -> 114.5
B35: ELIMINADOS | C35: % | D35: 0.01 | E35: 0.004 | F35: 0.004 | G35: 0.004 | H35: 0.005 | I35: 0.004 | J35: 0.005 | K35: 0.003 | L35: 0.003 | M35: 0.006 | N35: 0.004 | O35: 0.003 | P35: 0.003 | Q35: 0.003 | R35: 0.005 | S35: 0.002 | T35: 0.002 | U35: 0.002 | V35: 0.002 | W35: 0.002 | X35: 0.002 | Y35: 0.005 | Z35: 0.003 | AA35: 0.004 | AB35: 0.002 | AC35: 0.001 | AD35: 0.003 | AE35: 0.0022 | AF35: 0.0019 | AG35: 0.0027 | AH35: 0.0023 | AI35: 0.0016 | AJ35: 0.0025 | AK35: 0.0015 | AL35: 0.0024 | AM35: 0.00257 | AN35: 0.0025 | BA35: =IFERROR(AVERAGE(D35:O35),"-") -> 0.0045833333 | BB35: =IFERROR(AVERAGE(P35:AA35),"-") -> 0.0029166667 | BC35: =IFERROR(SUMIFS(AB35:AM35,AB35:AM35,"<>0",AB35:AM35,"<>-",AB35:AM35,"<>",AB35:AM35,"<> ")/COUNTIFS(AB35:AM35,"<>0",AB35:AM35,"<>-",AB35:AM35,"<>",AB35:AM35,"<> "),"-") -> 0.0021391667
B36: ETIQUETAS TOTALES | C36: UNI | P36: - | Q36: - | R36: - | S36: 2.56 | T36: 266 | U36: 315 | V36: 240 | W36: 309 | X36: 307 | Y36: 946 | Z36: 503 | AA36: 724 | AB36: 395 | AC36: 356 | AD36: 347 | AE36: 385 | AF36: 410 | AG36: 367 | AH36: 447 | AI36: 286 | AJ36: 418 | AK36: 295 | AL36: 389 | AM36: 531 | AN36: 537 | BA36: =IFERROR(AVERAGE(D36:O36),"-") -> - | BB36: =IFERROR(AVERAGE(P36:AA36),"-") -> 451.25 | BC36: =IFERROR(SUMIFS(AB36:AM36,AB36:AM36,"<>0",AB36:AM36,"<>-",AB36:AM36,"<>",AB36:AM36,"<> ")/COUNTIFS(AB36:AM36,"<>0",AB36:AM36,"<>-",AB36:AM36,"<>",AB36:AM36,"<> "),"-") -> 385.5
B37: ETIQUETAS REENVASADO | AB37: 42 | AC37: 47 | AD37: 18 | AE37: 64 | AF37: 65 | AG37: 16 | AH37: 44 | AI37: 5 | AJ37: 18 | AK37: 30 | AL37: 60 | AM37: 12 | AN37: 533 | BA37: =IFERROR(AVERAGE(D37:O37),"-") -> - | BB37: =IFERROR(AVERAGE(P37:AA37),"-") -> - | BC37: =IFERROR(SUMIFS(AB37:AM37,AB37:AM37,"<>0",AB37:AM37,"<>-",AB37:AM37,"<>",AB37:AM37,"<> ")/COUNTIFS(AB37:AM37,"<>0",AB37:AM37,"<>-",AB37:AM37,"<>",AB37:AM37,"<> "),"-") -> 35.083333
B38: ETIQUETAS H1 | AB38: 353 | AC38: 309 | AD38: 329 | AE38: 321 | AF38: 345 | AG38: 351 | AH38: 403 | AI38: 281 | AJ38: 400 | AK38: 265 | AL38: 329 | AM38: 519 | AN38: 4 | BA38: =IFERROR(AVERAGE(D38:O38),"-") -> - | BB38: =IFERROR(AVERAGE(P38:AA38),"-") -> - | BC38: =IFERROR(SUMIFS(AB38:AM38,AB38:AM38,"<>0",AB38:AM38,"<>-",AB38:AM38,"<>",AB38:AM38,"<> ")/COUNTIFS(AB38:AM38,"<>0",AB38:AM38,"<>-",AB38:AM38,"<>",AB38:AM38,"<> "),"-") -> 350.41667
B39: ETIQUETAS FISICAS/ JUSTIFICADAS | C39: UNI | P39: - | Q39: - | R39: - | S39: 116 | T39: 127 | U39: 186 | V39: 108 | W39: 147 | X39: 123 | Y39: 633 | Z39: 295 | AA39: 396 | AB39: 215 | AC39: - | AD39: - | AE39: - | AF39: - | AG39: - | AH39: 107 | AI39: - | AJ39: 170 | AK39: 16 | BA39: =IFERROR(AVERAGE(D39:O39),"-") -> - | BB39: =IFERROR(AVERAGE(P39:AA39),"-") -> 236.77778 | BC39: =IFERROR(SUMIFS(AB39:AM39,AB39:AM39,"<>0",AB39:AM39,"<>-",AB39:AM39,"<>",AB39:AM39,"<> ")/COUNTIFS(AB39:AM39,"<>0",AB39:AM39,"<>-",AB39:AM39,"<>",AB39:AM39,"<> "),"-") -> 84.666667
B40: REPROCESO - REPCAM | C40: KG | D40: 8154 | E40: 3402 | F40: 8517 | G40: 5136 | H40: 5745 | I40: 1141 | J40: 1677 | K40: 1061 | L40: 2965 | M40: 579 | N40: 2083 | O40: 2288 | P40: 794 | Q40: 1366 | R40: 2992 | S40: 5762 | T40: 8015 | U40: 1696 | V40: 2559 | W40: 1708 | X40: 3632 | Y40: 2.52 | Z40: 1489 | AA40: 2418 | AB40: 1015 | AG40: 10919.76 | AH40: 9135 | AI40: 16808 | AJ40: 4566 | AK40: 4640 | AL40: 6630 | AM40: 3022 | BA40: =IFERROR(AVERAGE(D40:O40),"-") -> 3562.3333 | BB40: =IFERROR(AVERAGE(P40:AA40),"-") -> 2948.2727 | BC40: =IFERROR(SUMIFS(AB40:AM40,AB40:AM40,"<>0",AB40:AM40,"<>-",AB40:AM40,"<>",AB40:AM40,"<> ")/COUNTIFS(AB40:AM40,"<>0",AB40:AM40,"<>-",AB40:AM40,"<>",AB40:AM40,"<> "),"-") -> 4727.98
B41: REPROCESO LEIDO | C41: KG | P41: - | Q41: - | R41: - | S41: - | T41: 4617 | U41: 1696 | V41: 2502 | W41: 1708 | X41: 82 | Y41: 2298 | Z41: 1489 | AA41: 2418 | AB41: 1015 | AG41: 5094.35 | AH41: 3638.83 | BA41: - | BB41: - | BC41: =IFERROR(SUMIFS(AB41:AM41,AB41:AM41,"<>0",AB41:AM41,"<>-",AB41:AM41,"<>",AB41:AM41,"<> ")/COUNTIFS(AB41:AM41,"<>0",AB41:AM41,"<>-",AB41:AM41,"<>",AB41:AM41,"<> "),"-") -> 1392.5971
...

Sheet TABLERO DIARIO
